Workbook

Sheet ANNUAL TOTAL
B1: FHSIS REPORT for the MONTH: JANUARY TO DECEMBER YEAR: 2023 | AK1: A2
B2: Name of Health Facility: RHU TRENTO
B3: Name of Barangay:
B4: Name of Municipality/City: TRENTO
B5: Name of Province: AGUSAN DEL SUR
B6: Projected Population of the Year: 57,388
B7: For submission to the next administrative level
A8: Disease | B8: ICD-10 Code | C8: 0-6 days | E8: 7-28 days | G8: 29 days- 11 mos | I8: 1-4 y/o | K8: 5-9 y/o | M8: 10-14 y/o | O8: 15-19 y/o | Q8: 20-24 y/o | S8: 25-29 y/o | U8: 30-34 y/o | W8: 35-39 y/o | Y8: 40-44 y/o | AA8: 45-49 y/o | AC8: 50-54 y/o | AE8: 55-59 y/o | AG8: 60-64 y/o | AI8: 65-69 y/o | AK8: ≥ 70 y/o | AM8: Total | AO8: TOTAL Both Sex
C9: M | D9: F | E9: M | F9: F | G9: M | H9: F | I9: M | J9: F | K9: M | L9: F | M9: M | N9: F | O9: M | P9: F | Q9: M | R9: F | S9: M | T9: F | U9: M | V9: F | W9: M | X9: F | Y9: M | Z9: F | AA9: M | AB9: F | AC9: M | AD9: F | AE9: M | AF9: F | AG9: M | AH9: F | AI9: M | AJ9: F | AK9: M | AL9: F | AM9: M | AN9: F
B10: SECTION A.1 MORBIDITY
A11: Other Diseases
A12: FOLLICULITIS | C12: ='1ST QUARTER'!C12+'2ND QUARTER'!C12+'3RD QUARTER'!C12+'4TH QUARTER'!C12 -> 0 | D12: ='1ST QUARTER'!D12+'2ND QUARTER'!D12+'3RD QUARTER'!D12+'4TH QUARTER'!D12 -> 0 | E12: ='1ST QUARTER'!E12+'2ND QUARTER'!E12+'3RD QUARTER'!E12+'4TH QUARTER'!E12 -> 0 | F12: ='1ST QUARTER'!F12+'2ND QUARTER'!F12+'3RD QUARTER'!F12+'4TH QUARTER'!F12 -> 0 | G12: ='1ST QUARTER'!G12+'2ND QUARTER'!G12+'3RD QUARTER'!G12+'4TH QUARTER'!G12 -> 0 | H12: ='1ST QUARTER'!H12+'2ND QUARTER'!H12+'3RD QUARTER'!H12+'4TH QUARTER'!H12 -> 0 | I12: ='1ST QUARTER'!I12+'2ND QUARTER'!I12+'3RD QUARTER'!I12+'4TH QUARTER'!I12 -> 0 | J12: ='1ST QUARTER'!J12+'2ND QUARTER'!J12+'3RD QUARTER'!J12+'4TH QUARTER'!J12 -> 0 | ... AL12: ='1ST QUARTER'!AL12+'2ND QUARTER'!AL12+'3RD QUARTER'!AL12+'4TH QUARTER'!AL12 -> 0 | AM12: =C12+E12+G12+I12+K12+M12+O12+Q12+S12+U12+W12+Y12+AA12+AC12+AE12+AG12+AI12+AK12 -> 0 | AN12: =D12+F12+H12+J12+L12+N12+P12+R12+T12+V12+X12+Z12+AB12+AD12+AF12+AH12+AJ12+AL12 -> 2 | AO12: =AM12+AN12 -> 2
A13: FRACTURE | C13: ='1ST QUARTER'!C13+'2ND QUARTER'!C13+'3RD QUARTER'!C13+'4TH QUARTER'!C13 -> 0 | D13: ='1ST QUARTER'!D13+'2ND QUARTER'!D13+'3RD QUARTER'!D13+'4TH QUARTER'!D13 -> 0 | E13: ='1ST QUARTER'!E13+'2ND QUARTER'!E13+'3RD QUARTER'!E13+'4TH QUARTER'!E13 -> 0 | F13: ='1ST QUARTER'!F13+'2ND QUARTER'!F13+'3RD QUARTER'!F13+'4TH QUARTER'!F13 -> 0 | G13: ='1ST QUARTER'!G13+'2ND QUARTER'!G13+'3RD QUARTER'!G13+'4TH QUARTER'!G13 -> 0 | H13: ='1ST QUARTER'!H13+'2ND QUARTER'!H13+'3RD QUARTER'!H13+'4TH QUARTER'!H13 -> 0 | I13: ='1ST QUARTER'!I13+'2ND QUARTER'!I13+'3RD QUARTER'!I13+'4TH QUARTER'!I13 -> 0 | J13: ='1ST QUARTER'!J13+'2ND QUARTER'!J13+'3RD QUARTER'!J13+'4TH QUARTER'!J13 -> 0 | ... AL13: ='1ST QUARTER'!AL13+'2ND QUARTER'!AL13+'3RD QUARTER'!AL13+'4TH QUARTER'!AL13 -> 0 | AM13: =C13+E13+G13+I13+K13+M13+O13+Q13+S13+U13+W13+Y13+AA13+AC13+AE13+AG13+AI13+AK13 -> 0 | AN13: =D13+F13+H13+J13+L13+N13+P13+R13+T13+V13+X13+Z13+AB13+AD13+AF13+AH13+AJ13+AL13 -> 0 | AO13: =AM13+AN13 -> 0
A14: IMPACTED CERUMEN | C14: ='1ST QUARTER'!C14+'2ND QUARTER'!C14+'3RD QUARTER'!C14+'4TH QUARTER'!C14 -> 0 | D14: ='1ST QUARTER'!D14+'2ND QUARTER'!D14+'3RD QUARTER'!D14+'4TH QUARTER'!D14 -> 0 | E14: ='1ST QUARTER'!E14+'2ND QUARTER'!E14+'3RD QUARTER'!E14+'4TH QUARTER'!E14 -> 0 | F14: ='1ST QUARTER'!F14+'2ND QUARTER'!F14+'3RD QUARTER'!F14+'4TH QUARTER'!F14 -> 0 | G14: ='1ST QUARTER'!G14+'2ND QUARTER'!G14+'3RD QUARTER'!G14+'4TH QUARTER'!G14 -> 0 | H14: ='1ST QUARTER'!H14+'2ND QUARTER'!H14+'3RD QUARTER'!H14+'4TH QUARTER'!H14 -> 0 | I14: ='1ST QUARTER'!I14+'2ND QUARTER'!I14+'3RD QUARTER'!I14+'4TH QUARTER'!I14 -> 0 | J14: ='1ST QUARTER'!J14+'2ND QUARTER'!J14+'3RD QUARTER'!J14+'4TH QUARTER'!J14 -> 0 | ... AL14: ='1ST QUARTER'!AL14+'2ND QUARTER'!AL14+'3RD QUARTER'!AL14+'4TH QUARTER'!AL14 -> 0 | AM14: =C14+E14+G14+I14+K14+M14+O14+Q14+S14+U14+W14+Y14+AA14+AC14+AE14+AG14+AI14+AK14 -> 0 | AN14: =D14+F14+H14+J14+L14+N14+P14+R14+T14+V14+X14+Z14+AB14+AD14+AF14+AH14+AJ14+AL14 -> 0 | AO14: =AM14+AN14 -> 0
A15: FATIGUE SYNCOPE | C15: ='1ST QUARTER'!C15+'2ND QUARTER'!C15+'3RD QUARTER'!C15+'4TH QUARTER'!C15 -> 0 | D15: ='1ST QUARTER'!D15+'2ND QUARTER'!D15+'3RD QUARTER'!D15+'4TH QUARTER'!D15 -> 0 | E15: ='1ST QUARTER'!E15+'2ND QUARTER'!E15+'3RD QUARTER'!E15+'4TH QUARTER'!E15 -> 0 | F15: ='1ST QUARTER'!F15+'2ND QUARTER'!F15+'3RD QUARTER'!F15+'4TH QUARTER'!F15 -> 0 | G15: ='1ST QUARTER'!G15+'2ND QUARTER'!G15+'3RD QUARTER'!G15+'4TH QUARTER'!G15 -> 0 | H15: ='1ST QUARTER'!H15+'2ND QUARTER'!H15+'3RD QUARTER'!H15+'4TH QUARTER'!H15 -> 0 | I15: ='1ST QUARTER'!I15+'2ND QUARTER'!I15+'3RD QUARTER'!I15+'4TH QUARTER'!I15 -> 0 | J15: ='1ST QUARTER'!J15+'2ND QUARTER'!J15+'3RD QUARTER'!J15+'4TH QUARTER'!J15 -> 0 | ... AL15: ='1ST QUARTER'!AL15+'2ND QUARTER'!AL15+'3RD QUARTER'!AL15+'4TH QUARTER'!AL15 -> 0 | AM15: =C15+E15+G15+I15+K15+M15+O15+Q15+S15+U15+W15+Y15+AA15+AC15+AE15+AG15+AI15+AK15 -> 0 | AN15: =D15+F15+H15+J15+L15+N15+P15+R15+T15+V15+X15+Z15+AB15+AD15+AF15+AH15+AJ15+AL15 -> 0 | AO15: =AM15+AN15 -> 0
A16: INFECTED ORAL AREA | C16: ='1ST QUARTER'!C16+'2ND QUARTER'!C16+'3RD QUARTER'!C16+'4TH QUARTER'!C16 -> 0 | D16: ='1ST QUARTER'!D16+'2ND QUARTER'!D16+'3RD QUARTER'!D16+'4TH QUARTER'!D16 -> 0 | E16: ='1ST QUARTER'!E16+'2ND QUARTER'!E16+'3RD QUARTER'!E16+'4TH QUARTER'!E16 -> 0 | F16: ='1ST QUARTER'!F16+'2ND QUARTER'!F16+'3RD QUARTER'!F16+'4TH QUARTER'!F16 -> 0 | G16: ='1ST QUARTER'!G16+'2ND QUARTER'!G16+'3RD QUARTER'!G16+'4TH QUARTER'!G16 -> 0 | H16: ='1ST QUARTER'!H16+'2ND QUARTER'!H16+'3RD QUARTER'!H16+'4TH QUARTER'!H16 -> 0 | I16: ='1ST QUARTER'!I16+'2ND QUARTER'!I16+'3RD QUARTER'!I16+'4TH QUARTER'!I16 -> 0 | J16: ='1ST QUARTER'!J16+'2ND QUARTER'!J16+'3RD QUARTER'!J16+'4TH QUARTER'!J16 -> 0 | ... AL16: ='1ST QUARTER'!AL16+'2ND QUARTER'!AL16+'3RD QUARTER'!AL16+'4TH QUARTER'!AL16 -> 0 | AM16: =C16+E16+G16+I16+K16+M16+O16+Q16+S16+U16+W16+Y16+AA16+AC16+AE16+AG16+AI16+AK16 -> 0 | AN16: =D16+F16+H16+J16+L16+N16+P16+R16+T16+V16+X16+Z16+AB16+AD16+AF16+AH16+AJ16+AL16 -> 0 | AO16: =AM16+AN16 -> 0
A17: NON ULCER DYSPEPSIA | C17: ='1ST QUARTER'!C17+'2ND QUARTER'!C17+'3RD QUARTER'!C17+'4TH QUARTER'!C17 -> 0 | D17: ='1ST QUARTER'!D17+'2ND QUARTER'!D17+'3RD QUARTER'!D17+'4TH QUARTER'!D17 -> 0 | E17: ='1ST QUARTER'!E17+'2ND QUARTER'!E17+'3RD QUARTER'!E17+'4TH QUARTER'!E17 -> 0 | F17: ='1ST QUARTER'!F17+'2ND QUARTER'!F17+'3RD QUARTER'!F17+'4TH QUARTER'!F17 -> 0 | G17: ='1ST QUARTER'!G17+'2ND QUARTER'!G17+'3RD QUARTER'!G17+'4TH QUARTER'!G17 -> 0 | H17: ='1ST QUARTER'!H17+'2ND QUARTER'!H17+'3RD QUARTER'!H17+'4TH QUARTER'!H17 -> 0 | I17: ='1ST QUARTER'!I17+'2ND QUARTER'!I17+'3RD QUARTER'!I17+'4TH QUARTER'!I17 -> 0 | J17: ='1ST QUARTER'!J17+'2ND QUARTER'!J17+'3RD QUARTER'!J17+'4TH QUARTER'!J17 -> 0 | ... AL17: ='1ST QUARTER'!AL17+'2ND QUARTER'!AL17+'3RD QUARTER'!AL17+'4TH QUARTER'!AL17 -> 0 | AM17: =C17+E17+G17+I17+K17+M17+O17+Q17+S17+U17+W17+Y17+AA17+AC17+AE17+AG17+AI17+AK17 -> 6 | AN17: =D17+F17+H17+J17+L17+N17+P17+R17+T17+V17+X17+Z17+AB17+AD17+AF17+AH17+AJ17+AL17 -> 6 | AO17: =AM17+AN17 -> 12
A18: TINEA CAPITIS | C18: ='1ST QUARTER'!C18+'2ND QUARTER'!C18+'3RD QUARTER'!C18+'4TH QUARTER'!C18 -> 0 | D18: ='1ST QUARTER'!D18+'2ND QUARTER'!D18+'3RD QUARTER'!D18+'4TH QUARTER'!D18 -> 0 | E18: ='1ST QUARTER'!E18+'2ND QUARTER'!E18+'3RD QUARTER'!E18+'4TH QUARTER'!E18 -> 0 | F18: ='1ST QUARTER'!F18+'2ND QUARTER'!F18+'3RD QUARTER'!F18+'4TH QUARTER'!F18 -> 0 | G18: ='1ST QUARTER'!G18+'2ND QUARTER'!G18+'3RD QUARTER'!G18+'4TH QUARTER'!G18 -> 0 | H18: ='1ST QUARTER'!H18+'2ND QUARTER'!H18+'3RD QUARTER'!H18+'4TH QUARTER'!H18 -> 0 | I18: ='1ST QUARTER'!I18+'2ND QUARTER'!I18+'3RD QUARTER'!I18+'4TH QUARTER'!I18 -> 0 | J18: ='1ST QUARTER'!J18+'2ND QUARTER'!J18+'3RD QUARTER'!J18+'4TH QUARTER'!J18 -> 0 | ... AL18: ='1ST QUARTER'!AL18+'2ND QUARTER'!AL18+'3RD QUARTER'!AL18+'4TH QUARTER'!AL18 -> 0 | AM18: =C18+E18+G18+I18+K18+M18+O18+Q18+S18+U18+W18+Y18+AA18+AC18+AE18+AG18+AI18+AK18 -> 0 | AN18: =D18+F18+H18+J18+L18+N18+P18+R18+T18+V18+X18+Z18+AB18+AD18+AF18+AH18+AJ18+AL18 -> 0 | AO18: =AM18+AN18 -> 0
A19: Bells Palsy | C19: ='1ST QUARTER'!C19+'2ND QUARTER'!C19+'3RD QUARTER'!C19+'4TH QUARTER'!C19 -> 0 | D19: ='1ST QUARTER'!D19+'2ND QUARTER'!D19+'3RD QUARTER'!D19+'4TH QUARTER'!D19 -> 0 | E19: ='1ST QUARTER'!E19+'2ND QUARTER'!E19+'3RD QUARTER'!E19+'4TH QUARTER'!E19 -> 0 | F19: ='1ST QUARTER'!F19+'2ND QUARTER'!F19+'3RD QUARTER'!F19+'4TH QUARTER'!F19 -> 0 | G19: ='1ST QUARTER'!G19+'2ND QUARTER'!G19+'3RD QUARTER'!G19+'4TH QUARTER'!G19 -> 0 | H19: ='1ST QUARTER'!H19+'2ND QUARTER'!H19+'3RD QUARTER'!H19+'4TH QUARTER'!H19 -> 0 | I19: ='1ST QUARTER'!I19+'2ND QUARTER'!I19+'3RD QUARTER'!I19+'4TH QUARTER'!I19 -> 0 | J19: ='1ST QUARTER'!J19+'2ND QUARTER'!J19+'3RD QUARTER'!J19+'4TH QUARTER'!J19 -> 0 | ... AL19: ='1ST QUARTER'!AL19+'2ND QUARTER'!AL19+'3RD QUARTER'!AL19+'4TH QUARTER'!AL19 -> 0 | AM19: =C19+E19+G19+I19+K19+M19+O19+Q19+S19+U19+W19+Y19+AA19+AC19+AE19+AG19+AI19+AK19 -> 0 | AN19: =D19+F19+H19+J19+L19+N19+P19+R19+T19+V19+X19+Z19+AB19+AD19+AF19+AH19+AJ19+AL19 -> 0 | AO19: =AM19+AN19 -> 0
A20: A
A21: ACUTE GASTRITIS | C21: ='1ST QUARTER'!C21+'2ND QUARTER'!C21+'3RD QUARTER'!C21+'4TH QUARTER'!C21 -> 0 | D21: ='1ST QUARTER'!D21+'2ND QUARTER'!D21+'3RD QUARTER'!D21+'4TH QUARTER'!D21 -> 0 | E21: ='1ST QUARTER'!E21+'2ND QUARTER'!E21+'3RD QUARTER'!E21+'4TH QUARTER'!E21 -> 0 | F21: ='1ST QUARTER'!F21+'2ND QUARTER'!F21+'3RD QUARTER'!F21+'4TH QUARTER'!F21 -> 0 | G21: ='1ST QUARTER'!G21+'2ND QUARTER'!G21+'3RD QUARTER'!G21+'4TH QUARTER'!G21 -> 0 | H21: ='1ST QUARTER'!H21+'2ND QUARTER'!H21+'3RD QUARTER'!H21+'4TH QUARTER'!H21 -> 0 | I21: ='1ST QUARTER'!I21+'2ND QUARTER'!I21+'3RD QUARTER'!I21+'4TH QUARTER'!I21 -> 6 | J21: ='1ST QUARTER'!J21+'2ND QUARTER'!J21+'3RD QUARTER'!J21+'4TH QUARTER'!J21 -> 4 | ... AL21: ='1ST QUARTER'!AL21+'2ND QUARTER'!AL21+'3RD QUARTER'!AL21+'4TH QUARTER'!AL21 -> 1 | AM21: =C21+E21+G21+I21+K21+M21+O21+Q21+S21+U21+W21+Y21+AA21+AC21+AE21+AG21+AI21+AK21 -> 24 | AN21: =D21+F21+H21+J21+L21+N21+P21+R21+T21+V21+X21+Z21+AB21+AD21+AF21+AH21+AJ21+AL21 -> 31 | AO21: =AM21+AN21 -> 55
A22: ASTHMA | C22: ='1ST QUARTER'!C22+'2ND QUARTER'!C22+'3RD QUARTER'!C22+'4TH QUARTER'!C22 -> 0 | D22: ='1ST QUARTER'!D22+'2ND QUARTER'!D22+'3RD QUARTER'!D22+'4TH QUARTER'!D22 -> 0 | E22: ='1ST QUARTER'!E22+'2ND QUARTER'!E22+'3RD QUARTER'!E22+'4TH QUARTER'!E22 -> 0 | F22: ='1ST QUARTER'!F22+'2ND QUARTER'!F22+'3RD QUARTER'!F22+'4TH QUARTER'!F22 -> 0 | G22: ='1ST QUARTER'!G22+'2ND QUARTER'!G22+'3RD QUARTER'!G22+'4TH QUARTER'!G22 -> 0 | H22: ='1ST QUARTER'!H22+'2ND QUARTER'!H22+'3RD QUARTER'!H22+'4TH QUARTER'!H22 -> 0 | I22: ='1ST QUARTER'!I22+'2ND QUARTER'!I22+'3RD QUARTER'!I22+'4TH QUARTER'!I22 -> 0 | J22: ='1ST QUARTER'!J22+'2ND QUARTER'!J22+'3RD QUARTER'!J22+'4TH QUARTER'!J22 -> 0 | ... AL22: ='1ST QUARTER'!AL22+'2ND QUARTER'!AL22+'3RD QUARTER'!AL22+'4TH QUARTER'!AL22 -> 0 | AM22: =C22+E22+G22+I22+K22+M22+O22+Q22+S22+U22+W22+Y22+AA22+AC22+AE22+AG22+AI22+AK22 -> 1 | AN22: =D22+F22+H22+J22+L22+N22+P22+R22+T22+V22+X22+Z22+AB22+AD22+AF22+AH22+AJ22+AL22 -> 0 | AO22: =AM22+AN22 -> 1
A23: ACUTE PYELONEPHRITIS | C23: ='1ST QUARTER'!C23+'2ND QUARTER'!C23+'3RD QUARTER'!C23+'4TH QUARTER'!C23 -> 0 | D23: ='1ST QUARTER'!D23+'2ND QUARTER'!D23+'3RD QUARTER'!D23+'4TH QUARTER'!D23 -> 0 | E23: ='1ST QUARTER'!E23+'2ND QUARTER'!E23+'3RD QUARTER'!E23+'4TH QUARTER'!E23 -> 0 | F23: ='1ST QUARTER'!F23+'2ND QUARTER'!F23+'3RD QUARTER'!F23+'4TH QUARTER'!F23 -> 0 | G23: ='1ST QUARTER'!G23+'2ND QUARTER'!G23+'3RD QUARTER'!G23+'4TH QUARTER'!G23 -> 0 | H23: ='1ST QUARTER'!H23+'2ND QUARTER'!H23+'3RD QUARTER'!H23+'4TH QUARTER'!H23 -> 0 | I23: ='1ST QUARTER'!I23+'2ND QUARTER'!I23+'3RD QUARTER'!I23+'4TH QUARTER'!I23 -> 0 | J23: ='1ST QUARTER'!J23+'2ND QUARTER'!J23+'3RD QUARTER'!J23+'4TH QUARTER'!J23 -> 0 | ... AL23: ='1ST QUARTER'!AL23+'2ND QUARTER'!AL23+'3RD QUARTER'!AL23+'4TH QUARTER'!AL23 -> 0 | AM23: =C23+E23+G23+I23+K23+M23+O23+Q23+S23+U23+W23+Y23+AA23+AC23+AE23+AG23+AI23+AK23 -> 0 | AN23: =D23+F23+H23+J23+L23+N23+P23+R23+T23+V23+X23+Z23+AB23+AD23+AF23+AH23+AJ23+AL23 -> 0 | AO23: =AM23+AN23 -> 0
A24: ANIMAL BITE | C24: ='1ST QUARTER'!C24+'2ND QUARTER'!C24+'3RD QUARTER'!C24+'4TH QUARTER'!C24 -> 0 | D24: ='1ST QUARTER'!D24+'2ND QUARTER'!D24+'3RD QUARTER'!D24+'4TH QUARTER'!D24 -> 0 | E24: ='1ST QUARTER'!E24+'2ND QUARTER'!E24+'3RD QUARTER'!E24+'4TH QUARTER'!E24 -> 0 | F24: ='1ST QUARTER'!F24+'2ND QUARTER'!F24+'3RD QUARTER'!F24+'4TH QUARTER'!F24 -> 0 | G24: ='1ST QUARTER'!G24+'2ND QUARTER'!G24+'3RD QUARTER'!G24+'4TH QUARTER'!G24 -> 0 | H24: ='1ST QUARTER'!H24+'2ND QUARTER'!H24+'3RD QUARTER'!H24+'4TH QUARTER'!H24 -> 0 | I24: ='1ST QUARTER'!I24+'2ND QUARTER'!I24+'3RD QUARTER'!I24+'4TH QUARTER'!I24 -> 0 | J24: ='1ST QUARTER'!J24+'2ND QUARTER'!J24+'3RD QUARTER'!J24+'4TH QUARTER'!J24 -> 0 | ... AL24: ='1ST QUARTER'!AL24+'2ND QUARTER'!AL24+'3RD QUARTER'!AL24+'4TH QUARTER'!AL24 -> 0 | AM24: =C24+E24+G24+I24+K24+M24+O24+Q24+S24+U24+W24+Y24+AA24+AC24+AE24+AG24+AI24+AK24 -> 0 | AN24: =D24+F24+H24+J24+L24+N24+P24+R24+T24+V24+X24+Z24+AB24+AD24+AF24+AH24+AJ24+AL24 -> 0 | AO24: =AM24+AN24 -> 0
A25: ABDOMINAL PAIN | C25: ='1ST QUARTER'!C25+'2ND QUARTER'!C25+'3RD QUARTER'!C25+'4TH QUARTER'!C25 -> 0 | D25: ='1ST QUARTER'!D25+'2ND QUARTER'!D25+'3RD QUARTER'!D25+'4TH QUARTER'!D25 -> 0 | E25: ='1ST QUARTER'!E25+'2ND QUARTER'!E25+'3RD QUARTER'!E25+'4TH QUARTER'!E25 -> 0 | F25: ='1ST QUARTER'!F25+'2ND QUARTER'!F25+'3RD QUARTER'!F25+'4TH QUARTER'!F25 -> 0 | G25: ='1ST QUARTER'!G25+'2ND QUARTER'!G25+'3RD QUARTER'!G25+'4TH QUARTER'!G25 -> 0 | H25: ='1ST QUARTER'!H25+'2ND QUARTER'!H25+'3RD QUARTER'!H25+'4TH QUARTER'!H25 -> 0 | I25: ='1ST QUARTER'!I25+'2ND QUARTER'!I25+'3RD QUARTER'!I25+'4TH QUARTER'!I25 -> 0 | J25: ='1ST QUARTER'!J25+'2ND QUARTER'!J25+'3RD QUARTER'!J25+'4TH QUARTER'!J25 -> 0 | ... AL25: ='1ST QUARTER'!AL25+'2ND QUARTER'!AL25+'3RD QUARTER'!AL25+'4TH QUARTER'!AL25 -> 0 | AM25: =C25+E25+G25+I25+K25+M25+O25+Q25+S25+U25+W25+Y25+AA25+AC25+AE25+AG25+AI25+AK25 -> 0 | AN25: =D25+F25+H25+J25+L25+N25+P25+R25+T25+V25+X25+Z25+AB25+AD25+AF25+AH25+AJ25+AL25 -> 0 | AO25: =AM25+AN25 -> 0
A26: ABRASION | C26: ='1ST QUARTER'!C26+'2ND QUARTER'!C26+'3RD QUARTER'!C26+'4TH QUARTER'!C26 -> 0 | D26: ='1ST QUARTER'!D26+'2ND QUARTER'!D26+'3RD QUARTER'!D26+'4TH QUARTER'!D26 -> 0 | E26: ='1ST QUARTER'!E26+'2ND QUARTER'!E26+'3RD QUARTER'!E26+'4TH QUARTER'!E26 -> 0 | F26: ='1ST QUARTER'!F26+'2ND QUARTER'!F26+'3RD QUARTER'!F26+'4TH QUARTER'!F26 -> 0 | G26: ='1ST QUARTER'!G26+'2ND QUARTER'!G26+'3RD QUARTER'!G26+'4TH QUARTER'!G26 -> 0 | H26: ='1ST QUARTER'!H26+'2ND QUARTER'!H26+'3RD QUARTER'!H26+'4TH QUARTER'!H26 -> 0 | I26: ='1ST QUARTER'!I26+'2ND QUARTER'!I26+'3RD QUARTER'!I26+'4TH QUARTER'!I26 -> 0 | J26: ='1ST QUARTER'!J26+'2ND QUARTER'!J26+'3RD QUARTER'!J26+'4TH QUARTER'!J26 -> 0 | ... AL26: ='1ST QUARTER'!AL26+'2ND QUARTER'!AL26+'3RD QUARTER'!AL26+'4TH QUARTER'!AL26 -> 0 | AM26: =C26+E26+G26+I26+K26+M26+O26+Q26+S26+U26+W26+Y26+AA26+AC26+AE26+AG26+AI26+AK26 -> 0 | AN26: =D26+F26+H26+J26+L26+N26+P26+R26+T26+V26+X26+Z26+AB26+AD26+AF26+AH26+AJ26+AL26 -> 0 | AO26: =AM26+AN26 -> 0
A27: ACUTE RESPIRATORY INFECTION/ DISEASE | C27: ='1ST QUARTER'!C27+'2ND QUARTER'!C27+'3RD QUARTER'!C27+'4TH QUARTER'!C27 -> 0 | D27: ='1ST QUARTER'!D27+'2ND QUARTER'!D27+'3RD QUARTER'!D27+'4TH QUARTER'!D27 -> 0 | E27: ='1ST QUARTER'!E27+'2ND QUARTER'!E27+'3RD QUARTER'!E27+'4TH QUARTER'!E27 -> 0 | F27: ='1ST QUARTER'!F27+'2ND QUARTER'!F27+'3RD QUARTER'!F27+'4TH QUARTER'!F27 -> 0 | G27: ='1ST QUARTER'!G27+'2ND QUARTER'!G27+'3RD QUARTER'!G27+'4TH QUARTER'!G27 -> 9 | H27: ='1ST QUARTER'!H27+'2ND QUARTER'!H27+'3RD QUARTER'!H27+'4TH QUARTER'!H27 -> 12 | I27: ='1ST QUARTER'!I27+'2ND QUARTER'!I27+'3RD QUARTER'!I27+'4TH QUARTER'!I27 -> 38 | J27: ='1ST QUARTER'!J27+'2ND QUARTER'!J27+'3RD QUARTER'!J27+'4TH QUARTER'!J27 -> 37 | ... AL27: ='1ST QUARTER'!AL27+'2ND QUARTER'!AL27+'3RD QUARTER'!AL27+'4TH QUARTER'!AL27 -> 5 | AM27: =C27+E27+G27+I27+K27+M27+O27+Q27+S27+U27+W27+Y27+AA27+AC27+AE27+AG27+AI27+AK27 -> 107 | AN27: =D27+F27+H27+J27+L27+N27+P27+R27+T27+V27+X27+Z27+AB27+AD27+AF27+AH27+AJ27+AL27 -> 109 | AO27: =AM27+AN27 -> 216
A28: ANEMIA | C28: ='1ST QUARTER'!C28+'2ND QUARTER'!C28+'3RD QUARTER'!C28+'4TH QUARTER'!C28 -> 0 | D28: ='1ST QUARTER'!D28+'2ND QUARTER'!D28+'3RD QUARTER'!D28+'4TH QUARTER'!D28 -> 0 | E28: ='1ST QUARTER'!E28+'2ND QUARTER'!E28+'3RD QUARTER'!E28+'4TH QUARTER'!E28 -> 0 | F28: ='1ST QUARTER'!F28+'2ND QUARTER'!F28+'3RD QUARTER'!F28+'4TH QUARTER'!F28 -> 0 | G28: ='1ST QUARTER'!G28+'2ND QUARTER'!G28+'3RD QUARTER'!G28+'4TH QUARTER'!G28 -> 0 | H28: ='1ST QUARTER'!H28+'2ND QUARTER'!H28+'3RD QUARTER'!H28+'4TH QUARTER'!H28 -> 0 | I28: ='1ST QUARTER'!I28+'2ND QUARTER'!I28+'3RD QUARTER'!I28+'4TH QUARTER'!I28 -> 0 | J28: ='1ST QUARTER'!J28+'2ND QUARTER'!J28+'3RD QUARTER'!J28+'4TH QUARTER'!J28 -> 0 | ... AL28: ='1ST QUARTER'!AL28+'2ND QUARTER'!AL28+'3RD QUARTER'!AL28+'4TH QUARTER'!AL28 -> 0 | AM28: =C28+E28+G28+I28+K28+M28+O28+Q28+S28+U28+W28+Y28+AA28+AC28+AE28+AG28+AI28+AK28 -> 0 | AN28: =D28+F28+H28+J28+L28+N28+P28+R28+T28+V28+X28+Z28+AB28+AD28+AF28+AH28+AJ28+AL28 -> 3 | AO28: =AM28+AN28 -> 3
A29: ACUTE UNCOMPLICATED CYSTITIS | C29: ='1ST QUARTER'!C29+'2ND QUARTER'!C29+'3RD QUARTER'!C29+'4TH QUARTER'!C29 -> 0 | D29: ='1ST QUARTER'!D29+'2ND QUARTER'!D29+'3RD QUARTER'!D29+'4TH QUARTER'!D29 -> 0 | E29: ='1ST QUARTER'!E29+'2ND QUARTER'!E29+'3RD QUARTER'!E29+'4TH QUARTER'!E29 -> 0 | F29: ='1ST QUARTER'!F29+'2ND QUARTER'!F29+'3RD QUARTER'!F29+'4TH QUARTER'!F29 -> 0 | G29: ='1ST QUARTER'!G29+'2ND QUARTER'!G29+'3RD QUARTER'!G29+'4TH QUARTER'!G29 -> 0 | H29: ='1ST QUARTER'!H29+'2ND QUARTER'!H29+'3RD QUARTER'!H29+'4TH QUARTER'!H29 -> 0 | I29: ='1ST QUARTER'!I29+'2ND QUARTER'!I29+'3RD QUARTER'!I29+'4TH QUARTER'!I29 -> 0 | J29: ='1ST QUARTER'!J29+'2ND QUARTER'!J29+'3RD QUARTER'!J29+'4TH QUARTER'!J29 -> 0 | ... AL29: ='1ST QUARTER'!AL29+'2ND QUARTER'!AL29+'3RD QUARTER'!AL29+'4TH QUARTER'!AL29 -> 0 | AM29: =C29+E29+G29+I29+K29+M29+O29+Q29+S29+U29+W29+Y29+AA29+AC29+AE29+AG29+AI29+AK29 -> 0 | AN29: =D29+F29+H29+J29+L29+N29+P29+R29+T29+V29+X29+Z29+AB29+AD29+AF29+AH29+AJ29+AL29 -> 2 | AO29: =AM29+AN29 -> 2
A30: ACUTE TONSILOPHARYNGITIS | C30: ='1ST QUARTER'!C30+'2ND QUARTER'!C30+'3RD QUARTER'!C30+'4TH QUARTER'!C30 -> 0 | D30: ='1ST QUARTER'!D30+'2ND QUARTER'!D30+'3RD QUARTER'!D30+'4TH QUARTER'!D30 -> 0 | E30: ='1ST QUARTER'!E30+'2ND QUARTER'!E30+'3RD QUARTER'!E30+'4TH QUARTER'!E30 -> 0 | F30: ='1ST QUARTER'!F30+'2ND QUARTER'!F30+'3RD QUARTER'!F30+'4TH QUARTER'!F30 -> 0 | G30: ='1ST QUARTER'!G30+'2ND QUARTER'!G30+'3RD QUARTER'!G30+'4TH QUARTER'!G30 -> 0 | H30: ='1ST QUARTER'!H30+'2ND QUARTER'!H30+'3RD QUARTER'!H30+'4TH QUARTER'!H30 -> 0 | I30: ='1ST QUARTER'!I30+'2ND QUARTER'!I30+'3RD QUARTER'!I30+'4TH QUARTER'!I30 -> 0 | J30: ='1ST QUARTER'!J30+'2ND QUARTER'!J30+'3RD QUARTER'!J30+'4TH QUARTER'!J30 -> 1 | ... AL30: ='1ST QUARTER'!AL30+'2ND QUARTER'!AL30+'3RD QUARTER'!AL30+'4TH QUARTER'!AL30 -> 0 | AM30: =C30+E30+G30+I30+K30+M30+O30+Q30+S30+U30+W30+Y30+AA30+AC30+AE30+AG30+AI30+AK30 -> 3 | AN30: =D30+F30+H30+J30+L30+N30+P30+R30+T30+V30+X30+Z30+AB30+AD30+AF30+AH30+AJ30+AL30 -> 8 | AO30: =AM30+AN30 -> 11
A31: ABCESS | C31: ='1ST QUARTER'!C31+'2ND QUARTER'!C31+'3RD QUARTER'!C31+'4TH QUARTER'!C31 -> 0 | D31: ='1ST QUARTER'!D31+'2ND QUARTER'!D31+'3RD QUARTER'!D31+'4TH QUARTER'!D31 -> 0 | E31: ='1ST QUARTER'!E31+'2ND QUARTER'!E31+'3RD QUARTER'!E31+'4TH QUARTER'!E31 -> 0 | F31: ='1ST QUARTER'!F31+'2ND QUARTER'!F31+'3RD QUARTER'!F31+'4TH QUARTER'!F31 -> 0 | G31: ='1ST QUARTER'!G31+'2ND QUARTER'!G31+'3RD QUARTER'!G31+'4TH QUARTER'!G31 -> 0 | H31: ='1ST QUARTER'!H31+'2ND QUARTER'!H31+'3RD QUARTER'!H31+'4TH QUARTER'!H31 -> 0 | I31: ='1ST QUARTER'!I31+'2ND QUARTER'!I31+'3RD QUARTER'!I31+'4TH QUARTER'!I31 -> 0 | J31: ='1ST QUARTER'!J31+'2ND QUARTER'!J31+'3RD QUARTER'!J31+'4TH QUARTER'!J31 -> 0 | ... AL31: ='1ST QUARTER'!AL31+'2ND QUARTER'!AL31+'3RD QUARTER'!AL31+'4TH QUARTER'!AL31 -> 0 | AM31: =C31+E31+G31+I31+K31+M31+O31+Q31+S31+U31+W31+Y31+AA31+AC31+AE31+AG31+AI31+AK31 -> 0 | AN31: =D31+F31+H31+J31+L31+N31+P31+R31+T31+V31+X31+Z31+AB31+AD31+AF31+AH31+AJ31+AL31 -> 0 | AO31: =AM31+AN31 -> 0
A32: ACUTE GASTROENTERITIS | C32: ='1ST QUARTER'!C32+'2ND QUARTER'!C32+'3RD QUARTER'!C32+'4TH QUARTER'!C32 -> 0 | D32: ='1ST QUARTER'!D32+'2ND QUARTER'!D32+'3RD QUARTER'!D32+'4TH QUARTER'!D32 -> 0 | E32: ='1ST QUARTER'!E32+'2ND QUARTER'!E32+'3RD QUARTER'!E32+'4TH QUARTER'!E32 -> 0 | F32: ='1ST QUARTER'!F32+'2ND QUARTER'!F32+'3RD QUARTER'!F32+'4TH QUARTER'!F32 -> 0 | G32: ='1ST QUARTER'!G32+'2ND QUARTER'!G32+'3RD QUARTER'!G32+'4TH QUARTER'!G32 -> 3 | H32: ='1ST QUARTER'!H32+'2ND QUARTER'!H32+'3RD QUARTER'!H32+'4TH QUARTER'!H32 -> 5 | I32: ='1ST QUARTER'!I32+'2ND QUARTER'!I32+'3RD QUARTER'!I32+'4TH QUARTER'!I32 -> 19 | J32: ='1ST QUARTER'!J32+'2ND QUARTER'!J32+'3RD QUARTER'!J32+'4TH QUARTER'!J32 -> 9 | ... AL32: ='1ST QUARTER'!AL32+'2ND QUARTER'!AL32+'3RD QUARTER'!AL32+'4TH QUARTER'!AL32 -> 0 | AM32: =C32+E32+G32+I32+K32+M32+O32+Q32+S32+U32+W32+Y32+AA32+AC32+AE32+AG32+AI32+AK32 -> 35 | AN32: =D32+F32+H32+J32+L32+N32+P32+R32+T32+V32+X32+Z32+AB32+AD32+AF32+AH32+AJ32+AL32 -> 32 | AO32: =AM32+AN32 -> 67
... A48: ACUTE CONJUNCTIVITIS | C48: ='1ST QUARTER'!C48+'2ND QUARTER'!C48+'3RD QUARTER'!C48+'4TH QUARTER'!C48 -> 0 | D48: ='1ST QUARTER'!D48+'2ND QUARTER'!D48+'3RD QUARTER'!D48+'4TH QUARTER'!D48 -> 0 | E48: ='1ST QUARTER'!E48+'2ND QUARTER'!E48+'3RD QUARTER'!E48+'4TH QUARTER'!E48 -> 0 | F48: ='1ST QUARTER'!F48+'2ND QUARTER'!F48+'3RD QUARTER'!F48+'4TH QUARTER'!F48 -> 0 | G48: ='1ST QUARTER'!G48+'2ND QUARTER'!G48+'3RD QUARTER'!G48+'4TH QUARTER'!G48 -> 0 | H48: ='1ST QUARTER'!H48+'2ND QUARTER'!H48+'3RD QUARTER'!H48+'4TH QUARTER'!H48 -> 0 | I48: ='1ST QUARTER'!I48+'2ND QUARTER'!I48+'3RD QUARTER'!I48+'4TH QUARTER'!I48 -> 0 | J48: ='1ST QUARTER'!J48+'2ND QUARTER'!J48+'3RD QUARTER'!J48+'4TH QUARTER'!J48 -> 0 | ... AL48: ='1ST QUARTER'!AL48+'2ND QUARTER'!AL48+'3RD QUARTER'!AL48+'4TH QUARTER'!AL48 -> 0 | AM48: =C48+E48+G48+I48+K48+M48+O48+Q48+S48+U48+W48+Y48+AA48+AC48+AE48+AG48+AI48+AK48 -> 1 | AN48: =D48+F48+H48+J48+L48+N48+P48+R48+T48+V48+X48+Z48+AB48+AD48+AF48+AH48+AJ48+AL48 -> 0 | AO48: =AM48+AN48 -> 1
A49: B
A50: BACTERIAL VAGINOSIS | C50: ='1ST QUARTER'!C50+'2ND QUARTER'!C50+'3RD QUARTER'!C50+'4TH QUARTER'!C50 -> 0 | D50: ='1ST QUARTER'!D50+'2ND QUARTER'!D50+'3RD QUARTER'!D50+'4TH QUARTER'!D50 -> 0 | E50: ='1ST QUARTER'!E50+'2ND QUARTER'!E50+'3RD QUARTER'!E50+'4TH QUARTER'!E50 -> 0 | F50: ='1ST QUARTER'!F50+'2ND QUARTER'!F50+'3RD QUARTER'!F50+'4TH QUARTER'!F50 -> 0 | G50: ='1ST QUARTER'!G50+'2ND QUARTER'!G50+'3RD QUARTER'!G50+'4TH QUARTER'!G50 -> 0 | H50: ='1ST QUARTER'!H50+'2ND QUARTER'!H50+'3RD QUARTER'!H50+'4TH QUARTER'!H50 -> 0 | I50: ='1ST QUARTER'!I50+'2ND QUARTER'!I50+'3RD QUARTER'!I50+'4TH QUARTER'!I50 -> 0 | J50: ='1ST QUARTER'!J50+'2ND QUARTER'!J50+'3RD QUARTER'!J50+'4TH QUARTER'!J50 -> 0 | ... AL50: ='1ST QUARTER'!AL50+'2ND QUARTER'!AL50+'3RD QUARTER'!AL50+'4TH QUARTER'!AL50 -> 0 | AM50: =C50+E50+G50+I50+K50+M50+O50+Q50+S50+U50+W50+Y50+AA50+AC50+AE50+AG50+AI50+AK50 -> 0 | AN50: =D50+F50+H50+J50+L50+N50+P50+R50+T50+V50+X50+Z50+AB50+AD50+AF50+AH50+AJ50+AL50 -> 0 | AO50: =AM50+AN50 -> 0
A51: BOILS | C51: ='1ST QUARTER'!C51+'2ND QUARTER'!C51+'3RD QUARTER'!C51+'4TH QUARTER'!C51 -> 0 | D51: ='1ST QUARTER'!D51+'2ND QUARTER'!D51+'3RD QUARTER'!D51+'4TH QUARTER'!D51 -> 0 | E51: ='1ST QUARTER'!E51+'2ND QUARTER'!E51+'3RD QUARTER'!E51+'4TH QUARTER'!E51 -> 0 | F51: ='1ST QUARTER'!F51+'2ND QUARTER'!F51+'3RD QUARTER'!F51+'4TH QUARTER'!F51 -> 0 | G51: ='1ST QUARTER'!G51+'2ND QUARTER'!G51+'3RD QUARTER'!G51+'4TH QUARTER'!G51 -> 0 | H51: ='1ST QUARTER'!H51+'2ND QUARTER'!H51+'3RD QUARTER'!H51+'4TH QUARTER'!H51 -> 0 | I51: ='1ST QUARTER'!I51+'2ND QUARTER'!I51+'3RD QUARTER'!I51+'4TH QUARTER'!I51 -> 0 | J51: ='1ST QUARTER'!J51+'2ND QUARTER'!J51+'3RD QUARTER'!J51+'4TH QUARTER'!J51 -> 0 | ... AL51: ='1ST QUARTER'!AL51+'2ND QUARTER'!AL51+'3RD QUARTER'!AL51+'4TH QUARTER'!AL51 -> 0 | AM51: =C51+E51+G51+I51+K51+M51+O51+Q51+S51+U51+W51+Y51+AA51+AC51+AE51+AG51+AI51+AK51 -> 0 | AN51: =D51+F51+H51+J51+L51+N51+P51+R51+T51+V51+X51+Z51+AB51+AD51+AF51+AH51+AJ51+AL51 -> 0 | AO51: =AM51+AN51 -> 0
A52: BENIGN PAROXYSMAL POSITIONAL VERTIGO | C52: ='1ST QUARTER'!C52+'2ND QUARTER'!C52+'3RD QUARTER'!C52+'4TH QUARTER'!C52 -> 0 | D52: ='1ST QUARTER'!D52+'2ND QUARTER'!D52+'3RD QUARTER'!D52+'4TH QUARTER'!D52 -> 0 | E52: ='1ST QUARTER'!E52+'2ND QUARTER'!E52+'3RD QUARTER'!E52+'4TH QUARTER'!E52 -> 0 | F52: ='1ST QUARTER'!F52+'2ND QUARTER'!F52+'3RD QUARTER'!F52+'4TH QUARTER'!F52 -> 0 | G52: ='1ST QUARTER'!G52+'2ND QUARTER'!G52+'3RD QUARTER'!G52+'4TH QUARTER'!G52 -> 0 | H52: ='1ST QUARTER'!H52+'2ND QUARTER'!H52+'3RD QUARTER'!H52+'4TH QUARTER'!H52 -> 0 | I52: ='1ST QUARTER'!I52+'2ND QUARTER'!I52+'3RD QUARTER'!I52+'4TH QUARTER'!I52 -> 0 | J52: ='1ST QUARTER'!J52+'2ND QUARTER'!J52+'3RD QUARTER'!J52+'4TH QUARTER'!J52 -> 0 | ... AL52: ='1ST QUARTER'!AL52+'2ND QUARTER'!AL52+'3RD QUARTER'!AL52+'4TH QUARTER'!AL52 -> 3 | AM52: =C52+E52+G52+I52+K52+M52+O52+Q52+S52+U52+W52+Y52+AA52+AC52+AE52+AG52+AI52+AK52 -> 24 | AN52: =D52+F52+H52+J52+L52+N52+P52+R52+T52+V52+X52+Z52+AB52+AD52+AF52+AH52+AJ52+AL52 -> 37 | AO52: =AM52+AN52 -> 61
A53: BACTERIAL INFECTION | C53: ='1ST QUARTER'!C53+'2ND QUARTER'!C53+'3RD QUARTER'!C53+'4TH QUARTER'!C53 -> 0 | D53: ='1ST QUARTER'!D53+'2ND QUARTER'!D53+'3RD QUARTER'!D53+'4TH QUARTER'!D53 -> 0 | E53: ='1ST QUARTER'!E53+'2ND QUARTER'!E53+'3RD QUARTER'!E53+'4TH QUARTER'!E53 -> 0 | F53: ='1ST QUARTER'!F53+'2ND QUARTER'!F53+'3RD QUARTER'!F53+'4TH QUARTER'!F53 -> 0 | G53: ='1ST QUARTER'!G53+'2ND QUARTER'!G53+'3RD QUARTER'!G53+'4TH QUARTER'!G53 -> 0 | H53: ='1ST QUARTER'!H53+'2ND QUARTER'!H53+'3RD QUARTER'!H53+'4TH QUARTER'!H53 -> 0 | I53: ='1ST QUARTER'!I53+'2ND QUARTER'!I53+'3RD QUARTER'!I53+'4TH QUARTER'!I53 -> 0 | J53: ='1ST QUARTER'!J53+'2ND QUARTER'!J53+'3RD QUARTER'!J53+'4TH QUARTER'!J53 -> 0 | ... AL53: ='1ST QUARTER'!AL53+'2ND QUARTER'!AL53+'3RD QUARTER'!AL53+'4TH QUARTER'!AL53 -> 0 | AM53: =C53+E53+G53+I53+K53+M53+O53+Q53+S53+U53+W53+Y53+AA53+AC53+AE53+AG53+AI53+AK53 -> 0 | AN53: =D53+F53+H53+J53+L53+N53+P53+R53+T53+V53+X53+Z53+AB53+AD53+AF53+AH53+AJ53+AL53 -> 0 | AO53: =AM53+AN53 -> 0
A54: BLEEDING (ALL TYPES) | C54: ='1ST QUARTER'!C54+'2ND QUARTER'!C54+'3RD QUARTER'!C54+'4TH QUARTER'!C54 -> 0 | D54: ='1ST QUARTER'!D54+'2ND QUARTER'!D54+'3RD QUARTER'!D54+'4TH QUARTER'!D54 -> 0 | E54: ='1ST QUARTER'!E54+'2ND QUARTER'!E54+'3RD QUARTER'!E54+'4TH QUARTER'!E54 -> 0 | F54: ='1ST QUARTER'!F54+'2ND QUARTER'!F54+'3RD QUARTER'!F54+'4TH QUARTER'!F54 -> 0 | G54: ='1ST QUARTER'!G54+'2ND QUARTER'!G54+'3RD QUARTER'!G54+'4TH QUARTER'!G54 -> 0 | H54: ='1ST QUARTER'!H54+'2ND QUARTER'!H54+'3RD QUARTER'!H54+'4TH QUARTER'!H54 -> 0 | I54: ='1ST QUARTER'!I54+'2ND QUARTER'!I54+'3RD QUARTER'!I54+'4TH QUARTER'!I54 -> 0 | J54: ='1ST QUARTER'!J54+'2ND QUARTER'!J54+'3RD QUARTER'!J54+'4TH QUARTER'!J54 -> 0 | ... AL54: ='1ST QUARTER'!AL54+'2ND QUARTER'!AL54+'3RD QUARTER'!AL54+'4TH QUARTER'!AL54 -> 0 | AM54: =C54+E54+G54+I54+K54+M54+O54+Q54+S54+U54+W54+Y54+AA54+AC54+AE54+AG54+AI54+AK54 -> 0 | AN54: =D54+F54+H54+J54+L54+N54+P54+R54+T54+V54+X54+Z54+AB54+AD54+AF54+AH54+AJ54+AL54 -> 0 | AO54: =AM54+AN54 -> 0
A55: BRONCHIAL ASTHMA | C55: ='1ST QUARTER'!C55+'2ND QUARTER'!C55+'3RD QUARTER'!C55+'4TH QUARTER'!C55 -> 0 | D55: ='1ST QUARTER'!D55+'2ND QUARTER'!D55+'3RD QUARTER'!D55+'4TH QUARTER'!D55 -> 0 | E55: ='1ST QUARTER'!E55+'2ND QUARTER'!E55+'3RD QUARTER'!E55+'4TH QUARTER'!E55 -> 0 | F55: ='1ST QUARTER'!F55+'2ND QUARTER'!F55+'3RD QUARTER'!F55+'4TH QUARTER'!F55 -> 0 | G55: ='1ST QUARTER'!G55+'2ND QUARTER'!G55+'3RD QUARTER'!G55+'4TH QUARTER'!G55 -> 0 | H55: ='1ST QUARTER'!H55+'2ND QUARTER'!H55+'3RD QUARTER'!H55+'4TH QUARTER'!H55 -> 0 | I55: ='1ST QUARTER'!I55+'2ND QUARTER'!I55+'3RD QUARTER'!I55+'4TH QUARTER'!I55 -> 0 | J55: ='1ST QUARTER'!J55+'2ND QUARTER'!J55+'3RD QUARTER'!J55+'4TH QUARTER'!J55 -> 0 | ... AL55: ='1ST QUARTER'!AL55+'2ND QUARTER'!AL55+'3RD QUARTER'!AL55+'4TH QUARTER'!AL55 -> 0 | AM55: =C55+E55+G55+I55+K55+M55+O55+Q55+S55+U55+W55+Y55+AA55+AC55+AE55+AG55+AI55+AK55 -> 0 | AN55: =D55+F55+H55+J55+L55+N55+P55+R55+T55+V55+X55+Z55+AB55+AD55+AF55+AH55+AJ55+AL55 -> 0 | AO55: =AM55+AN55 -> 0
...

Sheet JANUARY
B1: FHSIS REPORT for the MONTH: JANUARY YEAR: 2025 | AK1: M2
B2: Name of Health Facility: RHU-TRENTO
B3: Name of Barangay:
B4: Name of Municipality/City: TRENTO
B5: Name of Province: AGUSAN DEL SUR
B6: Projected Population of the Year: 57,388
B7: For submission to the next administrative level
A8: Disease | B8: ICD-10 Code | C8: 0-6 days | E8: 7-28 days | G8: 29 days- 11 mos | I8: 1-4 y/o | K8: 5-9 y/o | M8: 10-14 y/o | O8: 15-19 y/o | Q8: 20-24 y/o | S8: 25-29 y/o | U8: 30-34 y/o | W8: 35-39 y/o | Y8: 40-44 y/o | AA8: 45-49 y/o | AC8: 50-54 y/o | AE8: 55-59 y/o | AG8: 60-64 y/o | AI8: 65-69 y/o | AK8: ≥ 70 y/o | AM8: Total | AO8: TOTAL Both Sex
C9: M | D9: F | E9: M | F9: F | G9: M | H9: F | I9: M | J9: F | K9: M | L9: F | M9: M | N9: F | O9: M | P9: F | Q9: M | R9: F | S9: M | T9: F | U9: M | V9: F | W9: M | X9: F | Y9: M | Z9: F | AA9: M | AB9: F | AC9: M | AD9: F | AE9: M | AF9: F | AG9: M | AH9: F | AI9: M | AJ9: F | AK9: M | AL9: F | AM9: M | AN9: F
B10: SECTION A.1 MORBIDITY
A11: Other Diseases
A12: FOLLICULITIS | AM12: =C12+E12+G12+I12+K12+M12+O12+Q12+S12+U12+W12+Y12+AA12+AC12+AE12+AG12+AI12+AK12 -> 0 | AN12: =D12+F12+H12+J12+L12+N12+P12+R12+T12+V12+X12+Z12+AB12+AD12+AF12+AH12+AJ12+AL12 -> 0 | AO12: =AM12+AN12 -> 0
A13: FRACTURE | AM13: =C13+E13+G13+I13+K13+M13+O13+Q13+S13+U13+W13+Y13+AA13+AC13+AE13+AG13+AI13+AK13 -> 0 | AN13: =D13+F13+H13+J13+L13+N13+P13+R13+T13+V13+X13+Z13+AB13+AD13+AF13+AH13+AJ13+AL13 -> 0 | AO13: =AM13+AN13 -> 0
A14: IMPACTED CERUMEN | AM14: =C14+E14+G14+I14+K14+M14+O14+Q14+S14+U14+W14+Y14+AA14+AC14+AE14+AG14+AI14+AK14 -> 0 | AN14: =D14+F14+H14+J14+L14+N14+P14+R14+T14+V14+X14+Z14+AB14+AD14+AF14+AH14+AJ14+AL14 -> 0 | AO14: =AM14+AN14 -> 0
A15: FATIGUE SYNCOPE | AM15: =C15+E15+G15+I15+K15+M15+O15+Q15+S15+U15+W15+Y15+AA15+AC15+AE15+AG15+AI15+AK15 -> 0 | AN15: =D15+F15+H15+J15+L15+N15+P15+R15+T15+V15+X15+Z15+AB15+AD15+AF15+AH15+AJ15+AL15 -> 0 | AO15: =AM15+AN15 -> 0
A16: INFECTED ORAL AREA | AM16: =C16+E16+G16+I16+K16+M16+O16+Q16+S16+U16+W16+Y16+AA16+AC16+AE16+AG16+AI16+AK16 -> 0 | AN16: =D16+F16+H16+J16+L16+N16+P16+R16+T16+V16+X16+Z16+AB16+AD16+AF16+AH16+AJ16+AL16 -> 0 | AO16: =AM16+AN16 -> 0
A17: NON ULCER DYSPEPSIA | AM17: =C17+E17+G17+I17+K17+M17+O17+Q17+S17+U17+W17+Y17+AA17+AC17+AE17+AG17+AI17+AK17 -> 0 | AN17: =D17+F17+H17+J17+L17+N17+P17+R17+T17+V17+X17+Z17+AB17+AD17+AF17+AH17+AJ17+AL17 -> 0 | AO17: =AM17+AN17 -> 0
A18: TINEA CAPITIS | AM18: =C18+E18+G18+I18+K18+M18+O18+Q18+S18+U18+W18+Y18+AA18+AC18+AE18+AG18+AI18+AK18 -> 0 | AN18: =D18+F18+H18+J18+L18+N18+P18+R18+T18+V18+X18+Z18+AB18+AD18+AF18+AH18+AJ18+AL18 -> 0 | AO18: =AM18+AN18 -> 0
A19: Bells Palsy | AM19: =C19+E19+G19+I19+K19+M19+O19+Q19+S19+U19+W19+Y19+AA19+AC19+AE19+AG19+AI19+AK19 -> 0 | AN19: =D19+F19+H19+J19+L19+N19+P19+R19+T19+V19+X19+Z19+AB19+AD19+AF19+AH19+AJ19+AL19 -> 0 | AO19: =AM19+AN19 -> 0
A20: A | AM20: =C20+E20+G20+I20+K20+M20+O20+Q20+S20+U20+W20+Y20+AA20+AC20+AE20+AG20+AI20+AK20 -> 0 | AN20: =D20+F20+H20+J20+L20+N20+P20+R20+T20+V20+X20+Z20+AB20+AD20+AF20+AH20+AJ20+AL20 -> 0 | AO20: =AM20+AN20 -> 0
A21: ACUTE GASTRITIS | I21: 2 | J21: 1 | M21: 1 | AC21: 1 | AM21: =C21+E21+G21+I21+K21+M21+O21+Q21+S21+U21+W21+Y21+AA21+AC21+AE21+AG21+AI21+AK21 -> 4 | AN21: =D21+F21+H21+J21+L21+N21+P21+R21+T21+V21+X21+Z21+AB21+AD21+AF21+AH21+AJ21+AL21 -> 1 | AO21: =AM21+AN21 -> 5
A22: ASTHMA | AM22: =C22+E22+G22+I22+K22+M22+O22+Q22+S22+U22+W22+Y22+AA22+AC22+AE22+AG22+AI22+AK22 -> 0 | AN22: =D22+F22+H22+J22+L22+N22+P22+R22+T22+V22+X22+Z22+AB22+AD22+AF22+AH22+AJ22+AL22 -> 0 | AO22: =AM22+AN22 -> 0
A23: ACUTE PYELONEPHRITIS | AM23: =C23+E23+G23+I23+K23+M23+O23+Q23+S23+U23+W23+Y23+AA23+AC23+AE23+AG23+AI23+AK23 -> 0 | AN23: =D23+F23+H23+J23+L23+N23+P23+R23+T23+V23+X23+Z23+AB23+AD23+AF23+AH23+AJ23+AL23 -> 0 | AO23: =AM23+AN23 -> 0
A24: ANIMAL BITE | AM24: =C24+E24+G24+I24+K24+M24+O24+Q24+S24+U24+W24+Y24+AA24+AC24+AE24+AG24+AI24+AK24 -> 0 | AN24: =D24+F24+H24+J24+L24+N24+P24+R24+T24+V24+X24+Z24+AB24+AD24+AF24+AH24+AJ24+AL24 -> 0 | AO24: =AM24+AN24 -> 0
A25: ABDOMINAL PAIN | AM25: =C25+E25+G25+I25+K25+M25+O25+Q25+S25+U25+W25+Y25+AA25+AC25+AE25+AG25+AI25+AK25 -> 0 | AN25: =D25+F25+H25+J25+L25+N25+P25+R25+T25+V25+X25+Z25+AB25+AD25+AF25+AH25+AJ25+AL25 -> 0 | AO25: =AM25+AN25 -> 0
A26: ABRASION | AM26: =C26+E26+G26+I26+K26+M26+O26+Q26+S26+U26+W26+Y26+AA26+AC26+AE26+AG26+AI26+AK26 -> 0 | AN26: =D26+F26+H26+J26+L26+N26+P26+R26+T26+V26+X26+Z26+AB26+AD26+AF26+AH26+AJ26+AL26 -> 0 | AO26: =AM26+AN26 -> 0
A27: ACUTE RESPIRATORY INFECTION/ DISEASE | H27: 1 | I27: 5 | J27: 3 | L27: 2 | N27: 4 | O27: 2 | AM27: =C27+E27+G27+I27+K27+M27+O27+Q27+S27+U27+W27+Y27+AA27+AC27+AE27+AG27+AI27+AK27 -> 7 | AN27: =D27+F27+H27+J27+L27+N27+P27+R27+T27+V27+X27+Z27+AB27+AD27+AF27+AH27+AJ27+AL27 -> 10 | AO27: =AM27+AN27 -> 17
A28: ANEMIA | AM28: =C28+E28+G28+I28+K28+M28+O28+Q28+S28+U28+W28+Y28+AA28+AC28+AE28+AG28+AI28+AK28 -> 0 | AN28: =D28+F28+H28+J28+L28+N28+P28+R28+T28+V28+X28+Z28+AB28+AD28+AF28+AH28+AJ28+AL28 -> 0 | AO28: =AM28+AN28 -> 0
A29: ACUTE UNCOMPLICATED CYSTITIS | AM29: =C29+E29+G29+I29+K29+M29+O29+Q29+S29+U29+W29+Y29+AA29+AC29+AE29+AG29+AI29+AK29 -> 0 | AN29: =D29+F29+H29+J29+L29+N29+P29+R29+T29+V29+X29+Z29+AB29+AD29+AF29+AH29+AJ29+AL29 -> 0 | AO29: =AM29+AN29 -> 0
A30: ACUTE TONSILOPHARYNGITIS | M30: 1 | P30: 1 | AM30: =C30+E30+G30+I30+K30+M30+O30+Q30+S30+U30+W30+Y30+AA30+AC30+AE30+AG30+AI30+AK30 -> 1 | AN30: =D30+F30+H30+J30+L30+N30+P30+R30+T30+V30+X30+Z30+AB30+AD30+AF30+AH30+AJ30+AL30 -> 1 | AO30: =AM30+AN30 -> 2
A31: ABCESS | AM31: =C31+E31+G31+I31+K31+M31+O31+Q31+S31+U31+W31+Y31+AA31+AC31+AE31+AG31+AI31+AK31 -> 0 | AN31: =D31+F31+H31+J31+L31+N31+P31+R31+T31+V31+X31+Z31+AB31+AD31+AF31+AH31+AJ31+AL31 -> 0 | AO31: =AM31+AN31 -> 0
A32: ACUTE GASTROENTERITIS | I32: 6 | J32: 2 | L32: 2 | M32: 1 | N32: 1 | AE32: 1 | AM32: =C32+E32+G32+I32+K32+M32+O32+Q32+S32+U32+W32+Y32+AA32+AC32+AE32+AG32+AI32+AK32 -> 8 | AN32: =D32+F32+H32+J32+L32+N32+P32+R32+T32+V32+X32+Z32+AB32+AD32+AF32+AH32+AJ32+AL32 -> 5 | AO32: =AM32+AN32 -> 13
A33: ALLERGIC REACTION | AM33: =C33+E33+G33+I33+K33+M33+O33+Q33+S33+U33+W33+Y33+AA33+AC33+AE33+AG33+AI33+AK33 -> 0 | AN33: =D33+F33+H33+J33+L33+N33+P33+R33+T33+V33+X33+Z33+AB33+AD33+AF33+AH33+AJ33+AL33 -> 0 | AO33: =AM33+AN33 -> 0
A34: ACUTE GLOMERULONEPHRITIS | M34: 1 | AM34: =C34+E34+G34+I34+K34+M34+O34+Q34+S34+U34+W34+Y34+AA34+AC34+AE34+AG34+AI34+AK34 -> 1 | AN34: =D34+F34+H34+J34+L34+N34+P34+R34+T34+V34+X34+Z34+AB34+AD34+AF34+AH34+AJ34+AL34 -> 0 | AO34: =AM34+AN34 -> 1
A35: ANXIETY DISORDER | AM35: =C35+E35+G35+I35+K35+M35+O35+Q35+S35+U35+W35+Y35+AA35+AC35+AE35+AG35+AI35+AK35 -> 0 | AN35: =D35+F35+H35+J35+L35+N35+P35+R35+T35+V35+X35+Z35+AB35+AD35+AF35+AH35+AJ35+AL35 -> 0 | AO35: =AM35+AN35 -> 0
A36: ASYMPTOMATIC BACTERIURIA | AM36: =C36+E36+G36+I36+K36+M36+O36+Q36+S36+U36+W36+Y36+AA36+AC36+AE36+AG36+AI36+AK36 -> 0 | AN36: =D36+F36+H36+J36+L36+N36+P36+R36+T36+V36+X36+Z36+AB36+AD36+AF36+AH36+AJ36+AL36 -> 0 | AO36: =AM36+AN36 -> 0
A37: ATHEROSCLEROTIC AORTA | AM37: =C37+E37+G37+I37+K37+M37+O37+Q37+S37+U37+W37+Y37+AA37+AC37+AE37+AG37+AI37+AK37 -> 0 | AN37: =D37+F37+H37+J37+L37+N37+P37+R37+T37+V37+X37+Z37+AB37+AD37+AF37+AH37+AJ37+AL37 -> 0 | AO37: =AM37+AN37 -> 0
A38: ALLERGIC RHINITIS | AM38: =C38+E38+G38+I38+K38+M38+O38+Q38+S38+U38+W38+Y38+AA38+AC38+AE38+AG38+AI38+AK38 -> 0 | AN38: =D38+F38+H38+J38+L38+N38+P38+R38+T38+V38+X38+Z38+AB38+AD38+AF38+AH38+AJ38+AL38 -> 0 | AO38: =AM38+AN38 -> 0
A39: APPENDICITIS | AM39: =C39+E39+G39+I39+K39+M39+O39+Q39+S39+U39+W39+Y39+AA39+AC39+AE39+AG39+AI39+AK39 -> 0 | AN39: =D39+F39+H39+J39+L39+N39+P39+R39+T39+V39+X39+Z39+AB39+AD39+AF39+AH39+AJ39+AL39 -> 0 | AO39: =AM39+AN39 -> 0
A40: AMOEBIASIS | AM40: =C40+E40+G40+I40+K40+M40+O40+Q40+S40+U40+W40+Y40+AA40+AC40+AE40+AG40+AI40+AK40 -> 0 | AN40: =D40+F40+H40+J40+L40+N40+P40+R40+T40+V40+X40+Z40+AB40+AD40+AF40+AH40+AJ40+AL40 -> 0 | AO40: =AM40+AN40 -> 0
...

Sheet FEBRUARY
B1: FHSIS REPORT for the MONTH: FEBRUARY YEAR: 2025 | AK1: M2
B2: Name of Health Facility: RHU TRENTO
B3: Name of Barangay:
B4: Name of Municipality/City: TRENTO
B5: Name of Province: AGUSAN DEL SUR
B6: Projected Population of the Year: 57,388
B7: For submission to the next administrative level
A8: Disease | B8: ICD-10 Code | C8: 0-6 days | E8: 7-28 days | G8: 29 days- 11 mos | I8: 1-4 y/o | K8: 5-9 y/o | M8: 10-14 y/o | O8: 15-19 y/o | Q8: 20-24 y/o | S8: 25-29 y/o | U8: 30-34 y/o | W8: 35-39 y/o | Y8: 40-44 y/o | AA8: 45-49 y/o | AC8: 50-54 y/o | AE8: 55-59 y/o | AG8: 60-64 y/o | AI8: 65-69 y/o | AK8: ≥ 70 y/o | AM8: Total | AO8: TOTAL Both Sex
C9: M | D9: F | E9: M | F9: F | G9: M | H9: F | I9: M | J9: F | K9: M | L9: F | M9: M | N9: F | O9: M | P9: F | Q9: M | R9: F | S9: M | T9: F | U9: M | V9: F | W9: M | X9: F | Y9: M | Z9: F | AA9: M | AB9: F | AC9: M | AD9: F | AE9: M | AF9: F | AG9: M | AH9: F | AI9: M | AJ9: F | AK9: M | AL9: F | AM9: M | AN9: F
B10: SECTION A.1 MORBIDITY
A11: Other Diseases
A12: FOLLICULITIS | AM12: =C12+E12+G12+I12+K12+M12+O12+Q12+S12+U12+W12+Y12+AA12+AC12+AE12+AG12+AI12+AK12 -> 0 | AN12: =D12+F12+H12+J12+L12+N12+P12+R12+T12+V12+X12+Z12+AB12+AD12+AF12+AH12+AJ12+AL12 -> 0 | AO12: =AM12+AN12 -> 0
A13: FRACTURE | AM13: =C13+E13+G13+I13+K13+M13+O13+Q13+S13+U13+W13+Y13+AA13+AC13+AE13+AG13+AI13+AK13 -> 0 | AN13: =D13+F13+H13+J13+L13+N13+P13+R13+T13+V13+X13+Z13+AB13+AD13+AF13+AH13+AJ13+AL13 -> 0 | AO13: =AM13+AN13 -> 0
A14: IMPACTED CERUMEN | AM14: =C14+E14+G14+I14+K14+M14+O14+Q14+S14+U14+W14+Y14+AA14+AC14+AE14+AG14+AI14+AK14 -> 0 | AN14: =D14+F14+H14+J14+L14+N14+P14+R14+T14+V14+X14+Z14+AB14+AD14+AF14+AH14+AJ14+AL14 -> 0 | AO14: =AM14+AN14 -> 0
A15: FATIGUE SYNCOPE | AM15: =C15+E15+G15+I15+K15+M15+O15+Q15+S15+U15+W15+Y15+AA15+AC15+AE15+AG15+AI15+AK15 -> 0 | AN15: =D15+F15+H15+J15+L15+N15+P15+R15+T15+V15+X15+Z15+AB15+AD15+AF15+AH15+AJ15+AL15 -> 0 | AO15: =AM15+AN15 -> 0
A16: INFECTED ORAL AREA | AM16: =C16+E16+G16+I16+K16+M16+O16+Q16+S16+U16+W16+Y16+AA16+AC16+AE16+AG16+AI16+AK16 -> 0 | AN16: =D16+F16+H16+J16+L16+N16+P16+R16+T16+V16+X16+Z16+AB16+AD16+AF16+AH16+AJ16+AL16 -> 0 | AO16: =AM16+AN16 -> 0
A17: NON ULCER DYSPEPSIA | AM17: =C17+E17+G17+I17+K17+M17+O17+Q17+S17+U17+W17+Y17+AA17+AC17+AE17+AG17+AI17+AK17 -> 0 | AN17: =D17+F17+H17+J17+L17+N17+P17+R17+T17+V17+X17+Z17+AB17+AD17+AF17+AH17+AJ17+AL17 -> 0 | AO17: =AM17+AN17 -> 0
A18: TINEA CAPITIS | AM18: =C18+E18+G18+I18+K18+M18+O18+Q18+S18+U18+W18+Y18+AA18+AC18+AE18+AG18+AI18+AK18 -> 0 | AN18: =D18+F18+H18+J18+L18+N18+P18+R18+T18+V18+X18+Z18+AB18+AD18+AF18+AH18+AJ18+AL18 -> 0 | AO18: =AM18+AN18 -> 0
A19: Bells Palsy | AM19: =C19+E19+G19+I19+K19+M19+O19+Q19+S19+U19+W19+Y19+AA19+AC19+AE19+AG19+AI19+AK19 -> 0 | AN19: =D19+F19+H19+J19+L19+N19+P19+R19+T19+V19+X19+Z19+AB19+AD19+AF19+AH19+AJ19+AL19 -> 0 | AO19: =AM19+AN19 -> 0
A20: A | AM20: =C20+E20+G20+I20+K20+M20+O20+Q20+S20+U20+W20+Y20+AA20+AC20+AE20+AG20+AI20+AK20 -> 0 | AN20: =D20+F20+H20+J20+L20+N20+P20+R20+T20+V20+X20+Z20+AB20+AD20+AF20+AH20+AJ20+AL20 -> 0 | AO20: =AM20+AN20 -> 0
A21: ACUTE GASTRITIS | K21: 1 | N21: 1 | O21: 1 | Q21: 1 | R21: 1 | T21: 1 | AC21: 1 | AF21: 1 | AH21: 1 | AK21: 1 | AL21: 1 | AM21: =C21+E21+G21+I21+K21+M21+O21+Q21+S21+U21+W21+Y21+AA21+AC21+AE21+AG21+AI21+AK21 -> 5 | AN21: =D21+F21+H21+J21+L21+N21+P21+R21+T21+V21+X21+Z21+AB21+AD21+AF21+AH21+AJ21+AL21 -> 6 | AO21: =AM21+AN21 -> 11
A22: ASTHMA | AM22: =C22+E22+G22+I22+K22+M22+O22+Q22+S22+U22+W22+Y22+AA22+AC22+AE22+AG22+AI22+AK22 -> 0 | AN22: =D22+F22+H22+J22+L22+N22+P22+R22+T22+V22+X22+Z22+AB22+AD22+AF22+AH22+AJ22+AL22 -> 0 | AO22: =AM22+AN22 -> 0
A23: ACUTE PYELONEPHRITIS | AM23: =C23+E23+G23+I23+K23+M23+O23+Q23+S23+U23+W23+Y23+AA23+AC23+AE23+AG23+AI23+AK23 -> 0 | AN23: =D23+F23+H23+J23+L23+N23+P23+R23+T23+V23+X23+Z23+AB23+AD23+AF23+AH23+AJ23+AL23 -> 0 | AO23: =AM23+AN23 -> 0
A24: ANIMAL BITE | AM24: =C24+E24+G24+I24+K24+M24+O24+Q24+S24+U24+W24+Y24+AA24+AC24+AE24+AG24+AI24+AK24 -> 0 | AN24: =D24+F24+H24+J24+L24+N24+P24+R24+T24+V24+X24+Z24+AB24+AD24+AF24+AH24+AJ24+AL24 -> 0 | AO24: =AM24+AN24 -> 0
A25: ABDOMINAL PAIN | AM25: =C25+E25+G25+I25+K25+M25+O25+Q25+S25+U25+W25+Y25+AA25+AC25+AE25+AG25+AI25+AK25 -> 0 | AN25: =D25+F25+H25+J25+L25+N25+P25+R25+T25+V25+X25+Z25+AB25+AD25+AF25+AH25+AJ25+AL25 -> 0 | AO25: =AM25+AN25 -> 0
A26: ABRASION | AM26: =C26+E26+G26+I26+K26+M26+O26+Q26+S26+U26+W26+Y26+AA26+AC26+AE26+AG26+AI26+AK26 -> 0 | AN26: =D26+F26+H26+J26+L26+N26+P26+R26+T26+V26+X26+Z26+AB26+AD26+AF26+AH26+AJ26+AL26 -> 0 | AO26: =AM26+AN26 -> 0
A27: ACUTE RESPIRATORY INFECTION/ DISEASE | I27: 3 | J27: 1 | L27: 3 | N27: 2 | O27: 4 | P27: 1 | Q27: 4 | V27: 1 | X27: 1 | Y27: 2 | AB27: 1 | AM27: =C27+E27+G27+I27+K27+M27+O27+Q27+S27+U27+W27+Y27+AA27+AC27+AE27+AG27+AI27+AK27 -> 13 | AN27: =D27+F27+H27+J27+L27+N27+P27+R27+T27+V27+X27+Z27+AB27+AD27+AF27+AH27+AJ27+AL27 -> 10 | AO27: =AM27+AN27 -> 23
A28: ANEMIA | P28: 1 | X28: 1 | AM28: =C28+E28+G28+I28+K28+M28+O28+Q28+S28+U28+W28+Y28+AA28+AC28+AE28+AG28+AI28+AK28 -> 0 | AN28: =D28+F28+H28+J28+L28+N28+P28+R28+T28+V28+X28+Z28+AB28+AD28+AF28+AH28+AJ28+AL28 -> 2 | AO28: =AM28+AN28 -> 2
A29: ACUTE UNCOMPLICATED CYSTITIS | AM29: =C29+E29+G29+I29+K29+M29+O29+Q29+S29+U29+W29+Y29+AA29+AC29+AE29+AG29+AI29+AK29 -> 0 | AN29: =D29+F29+H29+J29+L29+N29+P29+R29+T29+V29+X29+Z29+AB29+AD29+AF29+AH29+AJ29+AL29 -> 0 | AO29: =AM29+AN29 -> 0
A30: ACUTE TONSILOPHARYNGITIS | AM30: =C30+E30+G30+I30+K30+M30+O30+Q30+S30+U30+W30+Y30+AA30+AC30+AE30+AG30+AI30+AK30 -> 0 | AN30: =D30+F30+H30+J30+L30+N30+P30+R30+T30+V30+X30+Z30+AB30+AD30+AF30+AH30+AJ30+AL30 -> 0 | AO30: =AM30+AN30 -> 0
A31: ABCESS | AM31: =C31+E31+G31+I31+K31+M31+O31+Q31+S31+U31+W31+Y31+AA31+AC31+AE31+AG31+AI31+AK31 -> 0 | AN31: =D31+F31+H31+J31+L31+N31+P31+R31+T31+V31+X31+Z31+AB31+AD31+AF31+AH31+AJ31+AL31 -> 0 | AO31: =AM31+AN31 -> 0
A32: ACUTE GASTROENTERITIS | I32: 3 | AM32: =C32+E32+G32+I32+K32+M32+O32+Q32+S32+U32+W32+Y32+AA32+AC32+AE32+AG32+AI32+AK32 -> 3 | AN32: =D32+F32+H32+J32+L32+N32+P32+R32+T32+V32+X32+Z32+AB32+AD32+AF32+AH32+AJ32+AL32 -> 0 | AO32: =AM32+AN32 -> 3
A33: ALLERGIC REACTION | AM33: =C33+E33+G33+I33+K33+M33+O33+Q33+S33+U33+W33+Y33+AA33+AC33+AE33+AG33+AI33+AK33 -> 0 | AN33: =D33+F33+H33+J33+L33+N33+P33+R33+T33+V33+X33+Z33+AB33+AD33+AF33+AH33+AJ33+AL33 -> 0 | AO33: =AM33+AN33 -> 0
A34: ACUTE GLOMERULONEPHRITIS | AM34: =C34+E34+G34+I34+K34+M34+O34+Q34+S34+U34+W34+Y34+AA34+AC34+AE34+AG34+AI34+AK34 -> 0 | AN34: =D34+F34+H34+J34+L34+N34+P34+R34+T34+V34+X34+Z34+AB34+AD34+AF34+AH34+AJ34+AL34 -> 0 | AO34: =AM34+AN34 -> 0
A35: ANXIETY DISORDER | AM35: =C35+E35+G35+I35+K35+M35+O35+Q35+S35+U35+W35+Y35+AA35+AC35+AE35+AG35+AI35+AK35 -> 0 | AN35: =D35+F35+H35+J35+L35+N35+P35+R35+T35+V35+X35+Z35+AB35+AD35+AF35+AH35+AJ35+AL35 -> 0 | AO35: =AM35+AN35 -> 0
A36: ASYMPTOMATIC BACTERIURIA | AM36: =C36+E36+G36+I36+K36+M36+O36+Q36+S36+U36+W36+Y36+AA36+AC36+AE36+AG36+AI36+AK36 -> 0 | AN36: =D36+F36+H36+J36+L36+N36+P36+R36+T36+V36+X36+Z36+AB36+AD36+AF36+AH36+AJ36+AL36 -> 0 | AO36: =AM36+AN36 -> 0
A37: ATHEROSCLEROTIC AORTA | AM37: =C37+E37+G37+I37+K37+M37+O37+Q37+S37+U37+W37+Y37+AA37+AC37+AE37+AG37+AI37+AK37 -> 0 | AN37: =D37+F37+H37+J37+L37+N37+P37+R37+T37+V37+X37+Z37+AB37+AD37+AF37+AH37+AJ37+AL37 -> 0 | AO37: =AM37+AN37 -> 0
A38: ALLERGIC RHINITIS | AM38: =C38+E38+G38+I38+K38+M38+O38+Q38+S38+U38+W38+Y38+AA38+AC38+AE38+AG38+AI38+AK38 -> 0 | AN38: =D38+F38+H38+J38+L38+N38+P38+R38+T38+V38+X38+Z38+AB38+AD38+AF38+AH38+AJ38+AL38 -> 0 | AO38: =AM38+AN38 -> 0
A39: APPENDICITIS | AM39: =C39+E39+G39+I39+K39+M39+O39+Q39+S39+U39+W39+Y39+AA39+AC39+AE39+AG39+AI39+AK39 -> 0 | AN39: =D39+F39+H39+J39+L39+N39+P39+R39+T39+V39+X39+Z39+AB39+AD39+AF39+AH39+AJ39+AL39 -> 0 | AO39: =AM39+AN39 -> 0
A40: AMOEBIASIS | AM40: =C40+E40+G40+I40+K40+M40+O40+Q40+S40+U40+W40+Y40+AA40+AC40+AE40+AG40+AI40+AK40 -> 0 | AN40: =D40+F40+H40+J40+L40+N40+P40+R40+T40+V40+X40+Z40+AB40+AD40+AF40+AH40+AJ40+AL40 -> 0 | AO40: =AM40+AN40 -> 0
...

Sheet MARCH
B1: FHSIS REPORT for the MONTH: MARCH YEAR: 2025 | AK1: M2
B2: Name of Health Facility: RHU TRENTO
B3: Name of Barangay:
B4: Name of Municipality/City: TRENTO
B5: Name of Province: AGUSAN DEL SUR
B6: Projected Population of the Year: 57,388
B7: For submission to the next administrative level
A8: Disease | B8: ICD-10 Code | C8: 0-6 days | E8: 7-28 days | G8: 29 days- 11 mos | I8: 1-4 y/o | K8: 5-9 y/o | M8: 10-14 y/o | O8: 15-19 y/o | Q8: 20-24 y/o | S8: 25-29 y/o | U8: 30-34 y/o | W8: 35-39 y/o | Y8: 40-44 y/o | AA8: 45-49 y/o | AC8: 50-54 y/o | AE8: 55-59 y/o | AG8: 60-64 y/o | AI8: 65-69 y/o | AK8: ≥ 70 y/o | AM8: Total | AO8: TOTAL Both Sex
C9: M | D9: F | E9: M | F9: F | G9: M | H9: F | I9: M | J9: F | K9: M | L9: F | M9: M | N9: F | O9: M | P9: F | Q9: M | R9: F | S9: M | T9: F | U9: M | V9: F | W9: M | X9: F | Y9: M | Z9: F | AA9: M | AB9: F | AC9: M | AD9: F | AE9: M | AF9: F | AG9: M | AH9: F | AI9: M | AJ9: F | AK9: M | AL9: F | AM9: M | AN9: F
B10: SECTION A.1 MORBIDITY
A11: Other Diseases
A12: FOLLICULITIS | AM12: =C12+E12+G12+I12+K12+M12+O12+Q12+S12+U12+W12+Y12+AA12+AC12+AE12+AG12+AI12+AK12 -> 0 | AN12: =D12+F12+H12+J12+L12+N12+P12+R12+T12+V12+X12+Z12+AB12+AD12+AF12+AH12+AJ12+AL12 -> 0 | AO12: =AM12+AN12 -> 0
A13: FRACTURE | AM13: =C13+E13+G13+I13+K13+M13+O13+Q13+S13+U13+W13+Y13+AA13+AC13+AE13+AG13+AI13+AK13 -> 0 | AN13: =D13+F13+H13+J13+L13+N13+P13+R13+T13+V13+X13+Z13+AB13+AD13+AF13+AH13+AJ13+AL13 -> 0 | AO13: =AM13+AN13 -> 0
A14: IMPACTED CERUMEN | AM14: =C14+E14+G14+I14+K14+M14+O14+Q14+S14+U14+W14+Y14+AA14+AC14+AE14+AG14+AI14+AK14 -> 0 | AN14: =D14+F14+H14+J14+L14+N14+P14+R14+T14+V14+X14+Z14+AB14+AD14+AF14+AH14+AJ14+AL14 -> 0 | AO14: =AM14+AN14 -> 0
A15: FATIGUE SYNCOPE | AM15: =C15+E15+G15+I15+K15+M15+O15+Q15+S15+U15+W15+Y15+AA15+AC15+AE15+AG15+AI15+AK15 -> 0 | AN15: =D15+F15+H15+J15+L15+N15+P15+R15+T15+V15+X15+Z15+AB15+AD15+AF15+AH15+AJ15+AL15 -> 0 | AO15: =AM15+AN15 -> 0
A16: INFECTED ORAL AREA | AM16: =C16+E16+G16+I16+K16+M16+O16+Q16+S16+U16+W16+Y16+AA16+AC16+AE16+AG16+AI16+AK16 -> 0 | AN16: =D16+F16+H16+J16+L16+N16+P16+R16+T16+V16+X16+Z16+AB16+AD16+AF16+AH16+AJ16+AL16 -> 0 | AO16: =AM16+AN16 -> 0
A17: NON ULCER DYSPEPSIA | P17: 1 | S17: 1 | AM17: =C17+E17+G17+I17+K17+M17+O17+Q17+S17+U17+W17+Y17+AA17+AC17+AE17+AG17+AI17+AK17 -> 1 | AN17: =D17+F17+H17+J17+L17+N17+P17+R17+T17+V17+X17+Z17+AB17+AD17+AF17+AH17+AJ17+AL17 -> 1 | AO17: =AM17+AN17 -> 2
A18: TINEA CAPITIS | AM18: =C18+E18+G18+I18+K18+M18+O18+Q18+S18+U18+W18+Y18+AA18+AC18+AE18+AG18+AI18+AK18 -> 0 | AN18: =D18+F18+H18+J18+L18+N18+P18+R18+T18+V18+X18+Z18+AB18+AD18+AF18+AH18+AJ18+AL18 -> 0 | AO18: =AM18+AN18 -> 0
A19: Bells Palsy | AM19: =C19+E19+G19+I19+K19+M19+O19+Q19+S19+U19+W19+Y19+AA19+AC19+AE19+AG19+AI19+AK19 -> 0 | AN19: =D19+F19+H19+J19+L19+N19+P19+R19+T19+V19+X19+Z19+AB19+AD19+AF19+AH19+AJ19+AL19 -> 0 | AO19: =AM19+AN19 -> 0
A20: A | AM20: =C20+E20+G20+I20+K20+M20+O20+Q20+S20+U20+W20+Y20+AA20+AC20+AE20+AG20+AI20+AK20 -> 0 | AN20: =D20+F20+H20+J20+L20+N20+P20+R20+T20+V20+X20+Z20+AB20+AD20+AF20+AH20+AJ20+AL20 -> 0 | AO20: =AM20+AN20 -> 0
A21: ACUTE GASTRITIS | M21: 1 | R21: 1 | AM21: =C21+E21+G21+I21+K21+M21+O21+Q21+S21+U21+W21+Y21+AA21+AC21+AE21+AG21+AI21+AK21 -> 1 | AN21: =D21+F21+H21+J21+L21+N21+P21+R21+T21+V21+X21+Z21+AB21+AD21+AF21+AH21+AJ21+AL21 -> 1 | AO21: =AM21+AN21 -> 2
A22: ASTHMA | AM22: =C22+E22+G22+I22+K22+M22+O22+Q22+S22+U22+W22+Y22+AA22+AC22+AE22+AG22+AI22+AK22 -> 0 | AN22: =D22+F22+H22+J22+L22+N22+P22+R22+T22+V22+X22+Z22+AB22+AD22+AF22+AH22+AJ22+AL22 -> 0 | AO22: =AM22+AN22 -> 0
A23: ACUTE PYELONEPHRITIS | AM23: =C23+E23+G23+I23+K23+M23+O23+Q23+S23+U23+W23+Y23+AA23+AC23+AE23+AG23+AI23+AK23 -> 0 | AN23: =D23+F23+H23+J23+L23+N23+P23+R23+T23+V23+X23+Z23+AB23+AD23+AF23+AH23+AJ23+AL23 -> 0 | AO23: =AM23+AN23 -> 0
A24: ANIMAL BITE | AM24: =C24+E24+G24+I24+K24+M24+O24+Q24+S24+U24+W24+Y24+AA24+AC24+AE24+AG24+AI24+AK24 -> 0 | AN24: =D24+F24+H24+J24+L24+N24+P24+R24+T24+V24+X24+Z24+AB24+AD24+AF24+AH24+AJ24+AL24 -> 0 | AO24: =AM24+AN24 -> 0
A25: ABDOMINAL PAIN | AM25: =C25+E25+G25+I25+K25+M25+O25+Q25+S25+U25+W25+Y25+AA25+AC25+AE25+AG25+AI25+AK25 -> 0 | AN25: =D25+F25+H25+J25+L25+N25+P25+R25+T25+V25+X25+Z25+AB25+AD25+AF25+AH25+AJ25+AL25 -> 0 | AO25: =AM25+AN25 -> 0
A26: ABRASION | AM26: =C26+E26+G26+I26+K26+M26+O26+Q26+S26+U26+W26+Y26+AA26+AC26+AE26+AG26+AI26+AK26 -> 0 | AN26: =D26+F26+H26+J26+L26+N26+P26+R26+T26+V26+X26+Z26+AB26+AD26+AF26+AH26+AJ26+AL26 -> 0 | AO26: =AM26+AN26 -> 0
A27: ACUTE RESPIRATORY INFECTION/ DISEASE | G27: 1 | I27: 2 | K27: 6 | M27: 1 | O27: 1 | X27: 1 | AM27: =C27+E27+G27+I27+K27+M27+O27+Q27+S27+U27+W27+Y27+AA27+AC27+AE27+AG27+AI27+AK27 -> 11 | AN27: =D27+F27+H27+J27+L27+N27+P27+R27+T27+V27+X27+Z27+AB27+AD27+AF27+AH27+AJ27+AL27 -> 1 | AO27: =AM27+AN27 -> 12
A28: ANEMIA | Z28: 1 | AM28: =C28+E28+G28+I28+K28+M28+O28+Q28+S28+U28+W28+Y28+AA28+AC28+AE28+AG28+AI28+AK28 -> 0 | AN28: =D28+F28+H28+J28+L28+N28+P28+R28+T28+V28+X28+Z28+AB28+AD28+AF28+AH28+AJ28+AL28 -> 1 | AO28: =AM28+AN28 -> 1
A29: ACUTE UNCOMPLICATED CYSTITIS | AM29: =C29+E29+G29+I29+K29+M29+O29+Q29+S29+U29+W29+Y29+AA29+AC29+AE29+AG29+AI29+AK29 -> 0 | AN29: =D29+F29+H29+J29+L29+N29+P29+R29+T29+V29+X29+Z29+AB29+AD29+AF29+AH29+AJ29+AL29 -> 0 | AO29: =AM29+AN29 -> 0
A30: ACUTE TONSILOPHARYNGITIS | N30: 1 | AM30: =C30+E30+G30+I30+K30+M30+O30+Q30+S30+U30+W30+Y30+AA30+AC30+AE30+AG30+AI30+AK30 -> 0 | AN30: =D30+F30+H30+J30+L30+N30+P30+R30+T30+V30+X30+Z30+AB30+AD30+AF30+AH30+AJ30+AL30 -> 1 | AO30: =AM30+AN30 -> 1
A31: ABCESS | AM31: =C31+E31+G31+I31+K31+M31+O31+Q31+S31+U31+W31+Y31+AA31+AC31+AE31+AG31+AI31+AK31 -> 0 | AN31: =D31+F31+H31+J31+L31+N31+P31+R31+T31+V31+X31+Z31+AB31+AD31+AF31+AH31+AJ31+AL31 -> 0
A32: ACUTE GASTROENTERITIS | H32: 2 | I32: 3 | J32: 4 | T32: 1 | AM32: =C32+E32+G32+I32+K32+M32+O32+Q32+S32+U32+W32+Y32+AA32+AC32+AE32+AG32+AI32+AK32 -> 3 | AN32: =D32+F32+H32+J32+L32+N32+P32+R32+T32+V32+X32+Z32+AB32+AD32+AF32+AH32+AJ32+AL32 -> 7 | AO32: =AM32+AN32 -> 10
A33: ALLERGIC REACTION | AM33: =C33+E33+G33+I33+K33+M33+O33+Q33+S33+U33+W33+Y33+AA33+AC33+AE33+AG33+AI33+AK33 -> 0 | AN33: =D33+F33+H33+J33+L33+N33+P33+R33+T33+V33+X33+Z33+AB33+AD33+AF33+AH33+AJ33+AL33 -> 0 | AO33: =AM33+AN33 -> 0
A34: ACUTE GLOMERULONEPHRITIS | AM34: =C34+E34+G34+I34+K34+M34+O34+Q34+S34+U34+W34+Y34+AA34+AC34+AE34+AG34+AI34+AK34 -> 0 | AN34: =D34+F34+H34+J34+L34+N34+P34+R34+T34+V34+X34+Z34+AB34+AD34+AF34+AH34+AJ34+AL34 -> 0 | AO34: =AM34+AN34 -> 0
A35: ANXIETY DISORDER | R35: 1 | AM35: =C35+E35+G35+I35+K35+M35+O35+Q35+S35+U35+W35+Y35+AA35+AC35+AE35+AG35+AI35+AK35 -> 0 | AN35: =D35+F35+H35+J35+L35+N35+P35+R35+T35+V35+X35+Z35+AB35+AD35+AF35+AH35+AJ35+AL35 -> 1 | AO35: =AM35+AN35 -> 1
A36: ASYMPTOMATIC BACTERIURIA | AM36: =C36+E36+G36+I36+K36+M36+O36+Q36+S36+U36+W36+Y36+AA36+AC36+AE36+AG36+AI36+AK36 -> 0 | AN36: =D36+F36+H36+J36+L36+N36+P36+R36+T36+V36+X36+Z36+AB36+AD36+AF36+AH36+AJ36+AL36 -> 0 | AO36: =AM36+AN36 -> 0
A37: ATHEROSCLEROTIC AORTA | AM37: =C37+E37+G37+I37+K37+M37+O37+Q37+S37+U37+W37+Y37+AA37+AC37+AE37+AG37+AI37+AK37 -> 0 | AN37: =D37+F37+H37+J37+L37+N37+P37+R37+T37+V37+X37+Z37+AB37+AD37+AF37+AH37+AJ37+AL37 -> 0 | AO37: =AM37+AN37 -> 0
A38: ALLERGIC RHINITIS | AM38: =C38+E38+G38+I38+K38+M38+O38+Q38+S38+U38+W38+Y38+AA38+AC38+AE38+AG38+AI38+AK38 -> 0 | AN38: =D38+F38+H38+J38+L38+N38+P38+R38+T38+V38+X38+Z38+AB38+AD38+AF38+AH38+AJ38+AL38 -> 0 | AO38: =AM38+AN38 -> 0
A39: APPENDICITIS | AM39: =C39+E39+G39+I39+K39+M39+O39+Q39+S39+U39+W39+Y39+AA39+AC39+AE39+AG39+AI39+AK39 -> 0 | AN39: =D39+F39+H39+J39+L39+N39+P39+R39+T39+V39+X39+Z39+AB39+AD39+AF39+AH39+AJ39+AL39 -> 0 | AO39: =AM39+AN39 -> 0
A40: AMOEBIASIS | AM40: =C40+E40+G40+I40+K40+M40+O40+Q40+S40+U40+W40+Y40+AA40+AC40+AE40+AG40+AI40+AK40 -> 0 | AN40: =D40+F40+H40+J40+L40+N40+P40+R40+T40+V40+X40+Z40+AB40+AD40+AF40+AH40+AJ40+AL40 -> 0 | AO40: =AM40+AN40 -> 0
...

Sheet 1ST QUARTER
B1: FHSIS REPORT for the MONTH: JANUARY TO MARCH YEAR: 2024 | AK1: Q1
B2: Name of Health Facility: RHU TRENTO
B3: Name of Barangay:
B4: Name of Municipality/City: TRENTO
B5: Name of Province: AGUSAN DEL SUR
B6: Projected Population of the Year: 56,690
B7: For submission to the next administrative level
A8: Disease | B8: ICD-10 Code | C8: 0-6 days | E8: 7-28 days | G8: 29 days- 11 mos | I8: 1-4 y/o | K8: 5-9 y/o | M8: 10-14 y/o | O8: 15-19 y/o | Q8: 20-24 y/o | S8: 25-29 y/o | U8: 30-34 y/o | W8: 35-39 y/o | Y8: 40-44 y/o | AA8: 45-49 y/o | AC8: 50-54 y/o | AE8: 55-59 y/o | AG8: 60-64 y/o | AI8: 65-69 y/o | AK8: ≥ 70 y/o | AM8: Total | AO8: TOTAL Both Sex
C9: M | D9: F | E9: M | F9: F | G9: M | H9: F | I9: M | J9: F | K9: M | L9: F | M9: M | N9: F | O9: M | P9: F | Q9: M | R9: F | S9: M | T9: F | U9: M | V9: F | W9: M | X9: F | Y9: M | Z9: F | AA9: M | AB9: F | AC9: M | AD9: F | AE9: M | AF9: F | AG9: M | AH9: F | AI9: M | AJ9: F | AK9: M | AL9: F | AM9: M | AN9: F
B10: SECTION A.1 MORBIDITY
A11: Other Diseases
A12: FOLLICULITIS | C12: =JANUARY!C12+FEBRUARY!C12+MARCH!C12 -> 0 | D12: =JANUARY!D12+FEBRUARY!D12+MARCH!D12 -> 0 | E12: =JANUARY!E12+FEBRUARY!E12+MARCH!E12 -> 0 | F12: =JANUARY!F12+FEBRUARY!F12+MARCH!F12 -> 0 | G12: =JANUARY!G12+FEBRUARY!G12+MARCH!G12 -> 0 | H12: =JANUARY!H12+FEBRUARY!H12+MARCH!H12 -> 0 | I12: =JANUARY!I12+FEBRUARY!I12+MARCH!I12 -> 0 | J12: =JANUARY!J12+FEBRUARY!J12+MARCH!J12 -> 0 | ... AL12: =JANUARY!AL12+FEBRUARY!AL12+MARCH!AL12 -> 0 | AM12: =C12+E12+G12+I12+K12+M12+O12+Q12+S12+U12+W12+Y12+AA12+AC12+AE12+AG12+AI12+AK12 -> 0 | AN12: =D12+F12+H12+J12+L12+N12+P12+R12+T12+V12+X12+Z12+AB12+AD12+AF12+AH12+AJ12+AL12 -> 0 | AO12: =AM12+AN12 -> 0
A13: FRACTURE | C13: =JANUARY!C13+FEBRUARY!C13+MARCH!C13 -> 0 | D13: =JANUARY!D13+FEBRUARY!D13+MARCH!D13 -> 0 | E13: =JANUARY!E13+FEBRUARY!E13+MARCH!E13 -> 0 | F13: =JANUARY!F13+FEBRUARY!F13+MARCH!F13 -> 0 | G13: =JANUARY!G13+FEBRUARY!G13+MARCH!G13 -> 0 | H13: =JANUARY!H13+FEBRUARY!H13+MARCH!H13 -> 0 | I13: =JANUARY!I13+FEBRUARY!I13+MARCH!I13 -> 0 | J13: =JANUARY!J13+FEBRUARY!J13+MARCH!J13 -> 0 | ... AL13: =JANUARY!AL13+FEBRUARY!AL13+MARCH!AL13 -> 0 | AM13: =C13+E13+G13+I13+K13+M13+O13+Q13+S13+U13+W13+Y13+AA13+AC13+AE13+AG13+AI13+AK13 -> 0 | AN13: =D13+F13+H13+J13+L13+N13+P13+R13+T13+V13+X13+Z13+AB13+AD13+AF13+AH13+AJ13+AL13 -> 0 | AO13: =AM13+AN13 -> 0
A14: IMPACTED CERUMEN | C14: =JANUARY!C14+FEBRUARY!C14+MARCH!C14 -> 0 | D14: =JANUARY!D14+FEBRUARY!D14+MARCH!D14 -> 0 | E14: =JANUARY!E14+FEBRUARY!E14+MARCH!E14 -> 0 | F14: =JANUARY!F14+FEBRUARY!F14+MARCH!F14 -> 0 | G14: =JANUARY!G14+FEBRUARY!G14+MARCH!G14 -> 0 | H14: =JANUARY!H14+FEBRUARY!H14+MARCH!H14 -> 0 | I14: =JANUARY!I14+FEBRUARY!I14+MARCH!I14 -> 0 | J14: =JANUARY!J14+FEBRUARY!J14+MARCH!J14 -> 0 | ... AL14: =JANUARY!AL14+FEBRUARY!AL14+MARCH!AL14 -> 0 | AM14: =C14+E14+G14+I14+K14+M14+O14+Q14+S14+U14+W14+Y14+AA14+AC14+AE14+AG14+AI14+AK14 -> 0 | AN14: =D14+F14+H14+J14+L14+N14+P14+R14+T14+V14+X14+Z14+AB14+AD14+AF14+AH14+AJ14+AL14 -> 0 | AO14: =AM14+AN14 -> 0
A15: FATIGUE SYNCOPE | C15: =JANUARY!C15+FEBRUARY!C15+MARCH!C15 -> 0 | D15: =JANUARY!D15+FEBRUARY!D15+MARCH!D15 -> 0 | E15: =JANUARY!E15+FEBRUARY!E15+MARCH!E15 -> 0 | F15: =JANUARY!F15+FEBRUARY!F15+MARCH!F15 -> 0 | G15: =JANUARY!G15+FEBRUARY!G15+MARCH!G15 -> 0 | H15: =JANUARY!H15+FEBRUARY!H15+MARCH!H15 -> 0 | I15: =JANUARY!I15+FEBRUARY!I15+MARCH!I15 -> 0 | J15: =JANUARY!J15+FEBRUARY!J15+MARCH!J15 -> 0 | ... AL15: =JANUARY!AL15+FEBRUARY!AL15+MARCH!AL15 -> 0 | AM15: =C15+E15+G15+I15+K15+M15+O15+Q15+S15+U15+W15+Y15+AA15+AC15+AE15+AG15+AI15+AK15 -> 0 | AN15: =D15+F15+H15+J15+L15+N15+P15+R15+T15+V15+X15+Z15+AB15+AD15+AF15+AH15+AJ15+AL15 -> 0 | AO15: =AM15+AN15 -> 0
A16: INFECTED ORAL AREA | C16: =JANUARY!C16+FEBRUARY!C16+MARCH!C16 -> 0 | D16: =JANUARY!D16+FEBRUARY!D16+MARCH!D16 -> 0 | E16: =JANUARY!E16+FEBRUARY!E16+MARCH!E16 -> 0 | F16: =JANUARY!F16+FEBRUARY!F16+MARCH!F16 -> 0 | G16: =JANUARY!G16+FEBRUARY!G16+MARCH!G16 -> 0 | H16: =JANUARY!H16+FEBRUARY!H16+MARCH!H16 -> 0 | I16: =JANUARY!I16+FEBRUARY!I16+MARCH!I16 -> 0 | J16: =JANUARY!J16+FEBRUARY!J16+MARCH!J16 -> 0 | ... AL16: =JANUARY!AL16+FEBRUARY!AL16+MARCH!AL16 -> 0 | AM16: =C16+E16+G16+I16+K16+M16+O16+Q16+S16+U16+W16+Y16+AA16+AC16+AE16+AG16+AI16+AK16 -> 0 | AN16: =D16+F16+H16+J16+L16+N16+P16+R16+T16+V16+X16+Z16+AB16+AD16+AF16+AH16+AJ16+AL16 -> 0 | AO16: =AM16+AN16 -> 0
A17: NON ULCER DYSPEPSIA | C17: =JANUARY!C17+FEBRUARY!C17+MARCH!C17 -> 0 | D17: =JANUARY!D17+FEBRUARY!D17+MARCH!D17 -> 0 | E17: =JANUARY!E17+FEBRUARY!E17+MARCH!E17 -> 0 | F17: =JANUARY!F17+FEBRUARY!F17+MARCH!F17 -> 0 | G17: =JANUARY!G17+FEBRUARY!G17+MARCH!G17 -> 0 | H17: =JANUARY!H17+FEBRUARY!H17+MARCH!H17 -> 0 | I17: =JANUARY!I17+FEBRUARY!I17+MARCH!I17 -> 0 | J17: =JANUARY!J17+FEBRUARY!J17+MARCH!J17 -> 0 | ... AL17: =JANUARY!AL17+FEBRUARY!AL17+MARCH!AL17 -> 0 | AM17: =C17+E17+G17+I17+K17+M17+O17+Q17+S17+U17+W17+Y17+AA17+AC17+AE17+AG17+AI17+AK17 -> 1 | AN17: =D17+F17+H17+J17+L17+N17+P17+R17+T17+V17+X17+Z17+AB17+AD17+AF17+AH17+AJ17+AL17 -> 1 | AO17: =AM17+AN17 -> 2
A18: TINEA CAPITIS | C18: =JANUARY!C18+FEBRUARY!C18+MARCH!C18 -> 0 | D18: =JANUARY!D18+FEBRUARY!D18+MARCH!D18 -> 0 | E18: =JANUARY!E18+FEBRUARY!E18+MARCH!E18 -> 0 | F18: =JANUARY!F18+FEBRUARY!F18+MARCH!F18 -> 0 | G18: =JANUARY!G18+FEBRUARY!G18+MARCH!G18 -> 0 | H18: =JANUARY!H18+FEBRUARY!H18+MARCH!H18 -> 0 | I18: =JANUARY!I18+FEBRUARY!I18+MARCH!I18 -> 0 | J18: =JANUARY!J18+FEBRUARY!J18+MARCH!J18 -> 0 | ... AL18: =JANUARY!AL18+FEBRUARY!AL18+MARCH!AL18 -> 0 | AM18: =C18+E18+G18+I18+K18+M18+O18+Q18+S18+U18+W18+Y18+AA18+AC18+AE18+AG18+AI18+AK18 -> 0 | AN18: =D18+F18+H18+J18+L18+N18+P18+R18+T18+V18+X18+Z18+AB18+AD18+AF18+AH18+AJ18+AL18 -> 0 | AO18: =AM18+AN18 -> 0
A19: Bells Palsy | C19: =JANUARY!C19+FEBRUARY!C19+MARCH!C19 -> 0 | D19: =JANUARY!D19+FEBRUARY!D19+MARCH!D19 -> 0 | E19: =JANUARY!E19+FEBRUARY!E19+MARCH!E19 -> 0 | F19: =JANUARY!F19+FEBRUARY!F19+MARCH!F19 -> 0 | G19: =JANUARY!G19+FEBRUARY!G19+MARCH!G19 -> 0 | H19: =JANUARY!H19+FEBRUARY!H19+MARCH!H19 -> 0 | I19: =JANUARY!I19+FEBRUARY!I19+MARCH!I19 -> 0 | J19: =JANUARY!J19+FEBRUARY!J19+MARCH!J19 -> 0 | ... AL19: =JANUARY!AL19+FEBRUARY!AL19+MARCH!AL19 -> 0 | AM19: =C19+E19+G19+I19+K19+M19+O19+Q19+S19+U19+W19+Y19+AA19+AC19+AE19+AG19+AI19+AK19 -> 0 | AN19: =D19+F19+H19+J19+L19+N19+P19+R19+T19+V19+X19+Z19+AB19+AD19+AF19+AH19+AJ19+AL19 -> 0 | AO19: =AM19+AN19 -> 0
A20: A
A21: ACUTE GASTRITIS | C21: =JANUARY!C21+FEBRUARY!C21+MARCH!C21 -> 0 | D21: =JANUARY!D21+FEBRUARY!D21+MARCH!D21 -> 0 | E21: =JANUARY!E21+FEBRUARY!E21+MARCH!E21 -> 0 | F21: =JANUARY!F21+FEBRUARY!F21+MARCH!F21 -> 0 | G21: =JANUARY!G21+FEBRUARY!G21+MARCH!G21 -> 0 | H21: =JANUARY!H21+FEBRUARY!H21+MARCH!H21 -> 0 | I21: =JANUARY!I21+FEBRUARY!I21+MARCH!I21 -> 2 | J21: =JANUARY!J21+FEBRUARY!J21+MARCH!J21 -> 1 | ... AL21: =JANUARY!AL21+FEBRUARY!AL21+MARCH!AL21 -> 1 | AM21: =C21+E21+G21+I21+K21+M21+O21+Q21+S21+U21+W21+Y21+AA21+AC21+AE21+AG21+AI21+AK21 -> 10 | AN21: =D21+F21+H21+J21+L21+N21+P21+R21+T21+V21+X21+Z21+AB21+AD21+AF21+AH21+AJ21+AL21 -> 8 | AO21: =AM21+AN21 -> 18
A22: ASTHMA | C22: =JANUARY!C22+FEBRUARY!C22+MARCH!C22 -> 0 | D22: =JANUARY!D22+FEBRUARY!D22+MARCH!D22 -> 0 | E22: =JANUARY!E22+FEBRUARY!E22+MARCH!E22 -> 0 | F22: =JANUARY!F22+FEBRUARY!F22+MARCH!F22 -> 0 | G22: =JANUARY!G22+FEBRUARY!G22+MARCH!G22 -> 0 | H22: =JANUARY!H22+FEBRUARY!H22+MARCH!H22 -> 0 | I22: =JANUARY!I22+FEBRUARY!I22+MARCH!I22 -> 0 | J22: =JANUARY!J22+FEBRUARY!J22+MARCH!J22 -> 0 | ... AL22: =JANUARY!AL22+FEBRUARY!AL22+MARCH!AL22 -> 0 | AM22: =C22+E22+G22+I22+K22+M22+O22+Q22+S22+U22+W22+Y22+AA22+AC22+AE22+AG22+AI22+AK22 -> 0 | AN22: =D22+F22+H22+J22+L22+N22+P22+R22+T22+V22+X22+Z22+AB22+AD22+AF22+AH22+AJ22+AL22 -> 0 | AO22: =AM22+AN22 -> 0
